Workbook

Sheet 안내
A1: PREP 경쟁사 DB & BM 매핑 수집 시트
A2: 작성 기준: db_구축_설계서.md V3.1 (2026-07-20) §3.5, §3.6, §6.3
A4: [시트 구성]
A5: ① competitors — 경쟁사 직접 조사 데이터를 입력하는 시트. 노란색 셀만 채우면 됨.
A6: ② bm_mapping — competitors에 입력된 (category_1, category_2, target, service_type, bm_pattern) 고유 조합을 자동으로 찾아
A7: frequency_score/precedent_level/contributing_competitor_ids까지 전부 수식으로 채우는 시트. 이 시트에는 직접 입력할 셀이 없음.
A8: → competitors에 새 행을 추가하고 bm_pattern까지 채우면, bm_mapping에 새 조합이 자동으로 나타남.
A10: [2026-07-20 변경] category(5종, 단일축) → category_1(질병축)+category_2(기능축) 2축으로 교체
A11: - category_1(질병축, 8종): 수면 / 정신건강 / 운동 / 식단 / 만성질환 / 여성건강 / 유전자 / 미용
A12: - category_2(기능축, 4종): 정보제공 / 데이터기록관리 / 매칭연결 / 개입치료
A13: - data_type(라이프스타일/생체지표)은 그대로 유지 — GATE 규제 판단·경쟁포화도 유사도 계산 전용, category_1/2와는 별개 축
A15: [자동 갱신이 안 될 때]
... A39: - evidence_id는 MVP 범위 제외(수동 큐레이션 정보라 VIEW로 표현 불가) — 필요 시 별도 참고용으로만 사용

Sheet competitors
A1: competitor_id | B1: name | C1: category_1 | D1: category_2 | E1: country | F1: tier | G1: data_type | H1: target | I1: service_type | J1: core_tags | K1: sub_tags | L1: bm_pattern | M1: note | N1: created_at | O1: updated_at | P1: updated_at | Q1: updated_at | R1: updated_at | S1: limitation | T1: price
A2: CP001 | B2: 눔(Noom) | C2: 식단 | D2: 개입치료 | E2: 미국 | F2: 카테고리리더 | G2: 라이프스타일 | H2: 다이어터,20-40대 | I2: 앱단독 | J2: 식단기록,체중관리 | K2: 커뮤니티,코칭 | L2: Subscription(구독형) | M2: 예시행 - 실제 데이터로 교체 | N2: 2026-07-20 | O2: 2026-07-20 | P2: =IF(L2="","",C2&"|"&D2&"|"&H2&"|"&I2&"|"&L2) | Q2: =IF(P2="",0,IF(COUNTIF($P$2:P2,P2)=1,1,0)) | R2: =IF(Q2=1,SUM($Q$2:Q2),"")
A3: CP002 | B3: 삼성헬스 | C3: 운동 | D3: 데이터기록관리 | E3: 한국 | F3: 플랫폼 | G3: 생체지표 | H3: 전연령 | I3: 웨어러블연동 | J3: 심박수,걸음수,수면 | K3: 스트레스지수 | L3: Lock-in(락인) | M3: 예시행 - 실제 데이터로 교체 | N3: 2026-07-20 | O3: 2026-07-20 | P3: =IF(L3="","",C3&"|"&D3&"|"&H3&"|"&I3&"|"&L3) | Q3: =IF(P3="",0,IF(COUNTIF($P$2:P3,P3)=1,1,0)) | R3: =IF(Q3=1,SUM($Q$2:Q3),"")
A4: CP003 | B4: 핑크 다이어리 | C4: 여성건강 | D4: 데이터기록관리 | E4: 한국 | F4: 카테고리리더 | G4: 라이프스타일 | H4: 가임기 여성 | I4: 앱단독 | J4: 생리주기,배란예측 | K4: 임신확률,매거진구독 | L4: Freemium(프리미엄) | M4: 대한산부인과의사회 공식앱, 누적설치 680만 | N4: 46225 | O4: 46225 | P4: =IF(L4="","",C4&"|"&D4&"|"&H4&"|"&I4&"|"&L4) | Q4: =IF(P4="",0,IF(COUNTIF($P$2:P4,P4)=1,1,0)) | R4: =IF(Q4=1,SUM($Q$2:Q4),"") | S4: 생리주기 예측은 통계적 추정 방식이라 개인차가 크고 배란일·임신 확률을 보장하지 않으며, 전문 의료 상담을 대체하지 않음 | T4: 기본 앱 무료(회원가입만으로 전 기능 이용 가능); 매거진 구독도 무료, 명확한 유료 인앱상품은 확인되지 않음
A5: CP004 | B5: 마미톡 | C5: 여성건강 | D5: 정보제공 | E5: 한국 | F5: 플랫폼 | G5: 라이프스타일 | H5: 임산부,초보양육자 | I5: 앱단독 | J5: 임신출산정보,커뮤니티 | K5: 육아용품쇼핑,전문가상담 | L5: Two-sided Market(양면시장) | M5: 대한민국 임신출산육아 대표앱 | N5: 46225 | O5: 46225 | P5: =IF(L5="","",C5&"|"&D5&"|"&H5&"|"&I5&"|"&L5) | Q5: =IF(P5="",0,IF(COUNTIF($P$2:P5,P5)=1,1,0)) | R5: =IF(Q5=1,SUM($Q$2:Q5),"") | S5: 분만병원 제휴 기반 광고·커머스 수익 구조라 정보 상당수가 협찬·판매 연계 콘텐츠일 수 있으며, 의료적 진단이나 상담을 대체하지 않음 | T5: 기본 앱·커뮤니티 이용 무료; 유료 전문가 클래스 멤버십 월 29,000원(1개월)~149,000원(12개월, 월환산 약 12,400원)
A6: CP005 | B6: 블룸 | C6: 여성건강 | D6: 개입치료 | E6: 한국 | F6: 일반경쟁자 | G6: 라이프스타일 | H6: 난임부부 | I6: B2B2C(기업복지제휴) | J6: 난임관리,임신준비프로그램 | K6: 난임시술케어,코칭 | L6: Performance-based Contracting(성과기반계약) | M6: LG화학 사내벤처, 기업 복지제휴 형태 | N6: 46225 | O6: 46225 | P6: =IF(L6="","",C6&"|"&D6&"|"&H6&"|"&I6&"|"&L6) | Q6: =IF(P6="",0,IF(COUNTIF($P$2:P6,P6)=1,1,0)) | R6: =IF(Q6=1,SUM($Q$2:Q6),"") | S6: LG화학의 특정 난임치료 사업과 연계된 기업 운영 앱으로, 콘텐츠가 자사 제품·파트너 병원 중심으로 편중될 수 있으며 실제 진료·시술은 제공하지 않음 | T6: 완전 무료(LG화학이 운영하는 기업 브랜드 앱, 별도 결제 없음)
A7: CP006 | B7: 자기만의방 | C7: 여성건강 | D7: 정보제공 | E7: 한국 | F7: 일반경쟁자 | G7: 라이프스타일 | H7: 여성 전연령 | I7: 앱단독 | J7: 성건강정보,커뮤니티 | K7: 이커머스연계 | L7: Freemium(프리미엄) | M7: 성 지식 콘텐츠, 커뮤니티 플랫폼 | N7: 46225 | O7: 46225 | P7: =IF(L7="","",C7&"|"&D7&"|"&H7&"|"&I7&"|"&L7) | Q7: =IF(P7="",0,IF(COUNTIF($P$2:P7,P7)=1,1,0)) | R7: =IF(Q7=1,SUM($Q$2:Q7),"") | S7: 성 지식 콘텐츠와 커머스 중심이라 의학적 진단이나 개인별 건강 상담 기능은 없으며, 심화 콘텐츠는 구독 결제가 필요함 | T7: 기본 콘텐츠·커뮤니티 무료; 전체 콘텐츠 무제한 이용 시 구독형 결제 월 4,900원 또는 연 47,000원
A8: CP007 | B8: 해피문데이 | C8: 여성건강 | D8: 개입치료 | E8: 한국 | F8: 일반경쟁자 | G8: 라이프스타일 | H8: 가임기여성 | I8: D2C구독 | J8: 유기농생리대,생리용품 | K8: 주기예측,정기배송 | L8: Subscription(구독형) | M8: 여성 헬스케어 기업, 중기부 TIPS 지원 기업 선정. 유기농 생리대 등 여성용품 정기구독 서비스 | N8: 46228 | O8: 46228 | P8: =IF(L8="","",C8&"|"&D8&"|"&H8&"|"&I8&"|"&L8) | Q8: =IF(P8="",0,IF(COUNTIF($P$2:P8,P8)=1,1,0)) | R8: =IF(Q8=1,SUM($Q$2:Q8),"") | S8: 여성용품 판매(D2C 커머스)가 핵심 수익원이라 앱의 건강정보·주기관리 기능이 결국 자사 제품 구매로 유도하는 구조이며, 의료 상담을 대체하지 않음 | T8: 앱·멤버십 자체 이용료는 없음; 유기농 생리대 등 제품은 건별 구매(중형 생리대 1팩 약 5,000~8,000원대)이며 정기구독 시 할인·무료배송 적용
A9: CP008 | B9: 렛허 | C9: 여성건강 | D9: 정보제공 | E9: 한국 | F9: 일반경쟁자 | G9: 라이프스타일 | H9: 2030 여성 | I9: 웹/커머스 | J9: 여성웰니스콘텐츠 | K9: 쇼핑몰 | L9: Add-on(애드온) | M9: 여성 웰니스 전문 미디어 & 쇼핑몰. 펨테크 얼라이언스 참여사 | N9: 46228 | O9: 46228 | P9: =IF(L9="","",C9&"|"&D9&"|"&H9&"|"&I9&"|"&L9) | Q9: =IF(P9="",0,IF(COUNTIF($P$2:P9,P9)=1,1,0)) | R9: =IF(Q9=1,SUM($Q$2:Q9),"") | S9: 미디어 콘텐츠와 커머스가 결합된 소규모 스타트업으로 판매 제품 소싱과 큐레이션 범위가 제한적이며, 자체 임상·의학적 검증을 거친 콘텐츠는 아님 | T9: 콘텐츠 열람은 무료; 매출은 쇼핑몰 제품 판매 기반이며 제품군별 가격 상이
A10: CP009 | B10: 달채비 | C10: 여성건강 | D10: 데이터기록관리 | E10: 한국 | F10: 일반경쟁자 | G10: 생체지표 | H10: 가임기여성 | I10: 앱단독 | J10: 월경데이터,AI맞춤추천 | K10: 여성건강습관코칭 | L10: Leverage Customer Data(데이터활용) | M10: 디에이엘컴퍼니(이화여대 창업팀) 운영. 월경 데이터를 분석해 개인별 월경용품·건강습관을 코칭하는 펨테크 앱 | N10: 46228 | O10: 46228 | P10: =IF(L10="","",C10&"|"&D10&"|"&H10&"|"&I10&"|"&L10) | Q10: =IF(P10="",0,IF(COUNTIF($P$2:P10,P10)=1,1,0)) | R10: =IF(Q10=1,SUM($Q$2:Q10),"") | S10: 이화여대 창업팀 기반의 초기 스타트업으로 이용자 규모와 수익모델이 아직 검증 단계이며, 월경·호르몬 분석 결과가 의학적 진단을 대체하지 않음 | T10: 앱 기본 기능 무료; 명확한 유료 구독 상품·결제 정보는 공개 자료에서 확인되지 않음(현재는 무료 서비스로 추정)
A11: CP010 | B11: 달다방 | C11: 여성건강 | D11: 데이터기록관리 | E11: 한국 | F11: 플랫폼 | G11: 라이프스타일 | H11: 여성 전연령(청소년 포함) | I11: 앱단독 | J11: 생리주기관리,초경교육 | K11: 커뮤니티,콘텐츠,커머스 | L11: Leverage Customer Data(데이터활용) | M11: 유한킴벌리가 직접 운영하는 여성건강 플랫폼. 2026년 5월 커머스·콘텐츠 결합형으로 대대적 개편, 멀티프로필로 가족 생리주기 관리 지원 | N11: 46229 | O11: 46229 | P11: =IF(L11="","",C11&"|"&D11&"|"&H11&"|"&I11&"|"&L11) | Q11: =IF(P11="",0,IF(COUNTIF($P$2:P11,P11)=1,1,0)) | R11: =IF(Q11=1,SUM($Q$2:Q11),"") | S11: 유한킴벌리 자사·제휴 여성용품 판매와 연계된 기업 운영 앱이라 추천 제품이 자사 브랜드 위주로 편중될 수 있음 | T11: 완전 무료(유한킴벌리가 직접 운영하는 브랜드 앱; 앱 내 커머스는 제품 구매 시에만 별도 결제)
A12: CP011 | B12: 베이비빌리 | C12: 여성건강 | D12: 정보제공 | E12: 한국 | F12: 카테고리리더 | G12: 라이프스타일 | H12: 임산부,예비부모 | I12: 앱단독 | J12: 임신육아정보,커뮤니티(베동) | K12: 빌리쇼핑(커머스) | L12: Two-sided Market(양면시장) | M12: 빌리지베이비 운영. 200만 이용자를 보유한 임신·육아 콘텐츠·커머스 앱으로 2025년 말~2026년 초에도 활발히 이벤트 진행 중 | N12: 46229 | O12: 46229 | P12: =IF(L12="","",C12&"|"&D12&"|"&H12&"|"&I12&"|"&L12) | Q12: =IF(P12="",0,IF(COUNTIF($P$2:P12,P12)=1,1,0)) | R12: =IF(Q12=1,SUM($Q$2:Q12),"") | S12: 커뮤니티 게시물에 대한 AI 자동 모니터링에 의존하는 구조라 잘못된 정보나 비검증 후기가 유통될 수 있으며, 전문 의료 상담을 대체하지 않음 | T12: 완전 무료(커뮤니티·콘텐츠·쇼핑 전 기능 무료 제공, 커머스 판매 수수료가 주요 수익원)
A13: CP012 | B13: 카이헬스 | C13: 여성건강 | D13: 개입치료 | E13: 한국 | F13: 일반경쟁자 | G13: 생체지표 | H13: 난임부부 | I13: B2B(의료기관 대상 SaaS) | J13: 난임AI솔루션,배아분석 | K13: 비타 엠브리오 | L13: Performance-based Contracting(성과기반계약) | M13: 산부인과 전문의 출신이 창업. AI로 배아 영상을 분석해 임신 성공률이 높은 배아를 선별하는 솔루션을 국내외 병원과 제휴해 제공 | N13: 46229 | O13: 46229 | P13: =IF(L13="","",C13&"|"&D13&"|"&H13&"|"&I13&"|"&L13) | Q13: =IF(P13="",0,IF(COUNTIF($P$2:P13,P13)=1,1,0)) | R13: =IF(Q13=1,SUM($Q$2:Q13),"") | S13: 일반 소비자가 직접 이용할 수 없고 제휴 의료기관을 통해서만 접근 가능하며, AI 배아 선별은 임신 성공률을 높이는 보조 수단일 뿐 시술 성공을 보장하지 않음 | T13: B2B(의료기관 대상 계약형) 솔루션으로 소비자 대상 공개 가격 없음; 병원별 계약 조건에 따라 이용료가 상이한 것으로 추정
A14: CP013 | B14: 듀이랩스(포이컵) | C14: 여성건강 | D14: 개입치료 | E14: 한국 | F14: 일반경쟁자 | G14: 라이프스타일 | H14: 가임기여성 | I14: D2C(제조판매) | J14: 월경디스크,다회용생리컵 | K14: 식약처·FDA 허가 | L14: Razor And Blade(레이저블레 | M14: 국내 최초 디스크형 월경컵 '포이컵'을 개발한 페미닌 헬스케어 스타트업. 2026년 기준 5년차 중소기업으로 운영 중 | N14: 46229 | O14: 46229 | P14: =IF(L14="","",C14&"|"&D14&"|"&H14&"|"&I14&"|"&L14) | Q14: =IF(P14="",0,IF(COUNTIF($P$2:P14,P14)=1,1,0)) | R14: =IF(Q14=1,SUM($Q$2:Q14),"") | S14: 삽입형 월경용품 특성상 신체 구조에 따라 착용감·적합도 차이가 크고, 원사이즈로만 판매돼 사용자에 따라 불편함을 느낄 수 있음 | T14: 포이컵 본품 정가 34,500원(1회 구매 후 반영구적 사용); 별도 구독료 없음
A15: CP014 | B15: 슈얼리(Surely) | C15: 여성건강 | D15: 개입치료 | E15: 한국 | F15: 일반경쟁자 | G15: 생체지표 | H15: 가임기~갱년기 여성 | I15: 기기+소모품(D2C) | J15: 배란테스트기,폐경호르몬(FSH)테스트기 | K15: 스마트기기 연동 | L15: Razor And Blade(레이저블레 | M15: 스마트 배란테스트기·임신테스트기·폐경호르몬테스트기를 기기 본체와 스트립(소모품) 형태로 판매하는 여성 호르몬 자가진단 브랜드 | N15: 46229 | O15: 46229 | P15: =IF(L15="","",C15&"|"&D15&"|"&H15&"|"&I15&"|"&L15) | Q15: =IF(P15="",0,IF(COUNTIF($P$2:P15,P15)=1,1,0)) | R15: =IF(Q15=1,SUM($Q$2:Q15),"") | S15: 스마트 기기와 스트립을 함께 구매해야 하는 소모품 구조로 초기 비용 부담이 있고, 자가진단 결과가 병원 호르몬 검사를 대체하지 않음 | T15: 스마트 기기 본체 약 5.8만원대(정가)에 테스트 스트립 10~30개입 1.4만~5만원대를 별도 구매; 비(非)스마트 스트립형은 1.4만~2만원대
... A25: CP024 | B25: 잼페이스 | C25: 미용 | D25: 정보제공 | E25: 한국 | F25: 일반경쟁자 | G25: 생체지표 | H25: 전연령뷰티소비자 | I25: 앱단독 | J25: AI퍼스널컬러진단,가상메이크업,화장품검색/추천 | K25: 리뷰,맞춤추천,쇼핑연계 | L25: Freemium(프리미엄) | M25: 2018년 출시, 정기 랭킹/투표 기반 화장품 큐레이션 서비스 | N25: 46225 | O25: 46225 | P25: =IF(L25="","",C25&"|"&D25&"|"&H25&"|"&I25&"|"&L25) | Q25: =IF(P25="",0,IF(COUNTIF($P$2:P25,P25)=1,1,0)) | R25: =IF(Q25=1,SUM($Q$2:Q25),"") | S25: AI 퍼스널컬러·피부진단이 카메라·조명 등 촬영 환경에 따라 정확도가 달라질 수 있고, 진단 결과가 협찬·광고 제품 추천으로 연결될 가능성이 있음 | T25: 앱 이용 무료; 화장품 매칭·광고 수익 기반
A26: CP025 | B26: 마메드네(구 카카오헤어샵) | C26: 미용 | D26: 매칭연결 | E26: 한국 | F26: 카테고리리더 | G26: 라이프스타일 | H26: 여성 전연령 | I26: 앱단독 | J26: 헤어샵예약,AI헤어시뮬레이션 | K26: 네일,왁싱,에스테틱 예약 | L26: Self-service(셀프서비스) | M26: 2016년 카카오헤어샵으로 출시, 2024년 스타트업 '글리티(Glity)'가 인수해 '마메드네'로 리브랜딩. AI 헤어 시뮬레이션으로 실제 디자이너 시술 포트폴리오 기반 스타일을 미리 확인 후 예약 가능 | N26: 46243 | O26: 46243 | P26: 예약 시스템을 도입한 매장 자체가 아직 많지 않아 이용 가능 지역·매장이 제한적이고, 실제 방문 시 이벤트 쿠폰 외 시술 가격은 저렴하지 않다는 이용자 불만이 있음 | Q26: 앱 이용(고객용) 무료; 실제 시술 요금은 매장별 상이하며 회원 전용 월간 쿠폰으로 할인 제공 | R26: =IF(Q26=1,SUM($Q$2:Q26),"") | S26: 예약 시스템을 도입한 매장 자체가 아직 많지 않아 이용 가능 지역·매장이 제한적이고, 실제 방문 시 이벤트 쿠폰 외 시술 가격은 저렴하지 않다는 이용자 불만이 있음 | T26: 앱 이용(고객용) 무료; 실제 시술 요금은 매장별 상이하며 회원 전용 월간 쿠폰으로 할인 제공
A27: CP026 | B27: Sephora | C27: 미용 | D27: 매칭연결 | E27: 미국 | F27: 플랫폼 | G27: 라이프스타일 | H27: 전연령뷰티소비자 | I27: 앱단독 | J27: 화장품검색/쇼핑, 리뷰,가상메이크업,상담 | K27: AI맞춤추천,뷰티클래스 | L27: Two-sided Market(양면시장) | M27: 뷰티 커머스 + 로열티 플랫폼 | N27: 46225 | O27: 46225 | P27: =IF(L27="","",C27&"|"&D27&"|"&H27&"|"&I27&"|"&L27) | Q27: =IF(P27="",0,IF(COUNTIF($P$2:P27,P27)=1,1,0)) | R27: =IF(Q27=1,SUM($Q$2:Q27),"") | S27: 한국 시장에서는 코로나19와 올리브영 등 경쟁에 밀려 2024년 5월 오프라인 매장·온라인몰·앱을 모두 철수했으며, 이후 국내 이용자는 해외(미국 등) 계정과 배송으로만 접근 가능함 | T27: 앱 이용 무료; 로열티 프로그램(Beauty Insider) 무료 가입, 등급별 혜택 차등, 상품은 개별 구매가
A28: CP027 | B28: Musely | C28: 미용 | D28: 개입치료 | E28: 미국 | F28: 일반경쟁자 | G28: 라이프스타일 | H28: 피부트러블여성 | I28: 원격진료연계 | J28: AI피부분석,처방연계 | K28: AI기반맞춤스킨케어루틴추천,피부관리콘텐츠 | L28: Subscription(구독형) | M28: AI 피부분석 후 처방 연계형 스킨케어 | N28: 46225 | O28: 46225 | P28: =IF(L28="","",C28&"|"&D28&"|"&H28&"|"&I28&"|"&L28) | Q28: =IF(P28="",0,IF(COUNTIF($P$2:P28,P28)=1,1,0)) | R28: =IF(Q28=1,SUM($Q$2:Q28),"") | S28: 미국 원격의료 규제 하에서 운영되는 서비스로 한국에서는 정식 이용이 불가능하며, 처방 연계 스킨케어는 의사의 원격 진단 결과에 의존함 | T28: 앱 이용 무료; AI 피부분석 후 처방이 필요하면 원격진료·처방 스킨케어 비용이 별도 발생(미국 기준 월 구독형)
A29: CP028 | B29: 마인드카페 | C29: 정신건강 | D29: 매칭연결 | E29: 한국 | F29: 카테고리리더 | G29: 라이프스타일 | H29: 개인,기업임직원 | I29: 심리상담/멘탈케어 플랫폼 | J29: 심리상담,코칭,EAP | K29: 익명커뮤니티,심리검사,온오프라인상담 | L29: Two-sided Market(양면시장) | M29: 국내 대표 멘탈케어 플랫폼, 개인 상담과 기업 EAP 모두 운영 | N29: 46225 | O29: 46225 | P29: 정신건강|매칭연결|개인,기업임직원|심리상담/멘탈케어 플랫폼|Two-sided Market(양면시장) | Q29: 1 | R29: 25 | S29: 상담 품질과 결과가 상담사 역량 및 매칭 적합도에 크게 좌우되며, 상담 이용료가 누적되면 비용 부담이 커질 수 있음 | T29: 온라인 심리상담 1회기 43,000원부터; 코칭상담 1회기 40,000원부터; 심리검사·해석상담 25,000~75,000원; 오프라인·검사 상품별 상이
A30: CP029 | B30: 트로스트 | C30: 정신건강 | D30: 매칭연결 | E30: 한국 | F30: 일반경쟁자 | G30: 라이프스타일 | H30: 개인 | I30: 비대면 심리상담 앱 | J30: 심리상담,심리검사,명상 | K30: 상담사매칭,커뮤니티,텍스트상담 | L30: Two-sided Market(양면시장) | M30: 국내 비대면 심리상담 앱, 상담사 매칭과 심리검사 제공 | N30: 46225 | O30: 46225 | P30: 정신건강|매칭연결|개인|비대면 심리상담 앱|Two-sided Market(양면시장) | Q30: 1 | R30: 26 | S30: 비대면 상담 중심이라 대면 상담 대비 관계 형성과 비언어적 정보 전달에 한계가 있으며, 상담사별 가격과 품질 편차가 존재함 | T30: 텍스트 테라피 1일권 15,000원, 7일권 40,000원, 30일권 100,000원, 90일권 240,000원; 전화상담 30분 40,000원; 화상상담 30분 50,000원
A31: CP030 | B31: 마보 | C31: 정신건강 | D31: 정보제공 | E31: 한국 | F31: 카테고리리더 | G31: 라이프스타일 | H31: 개인,기업임직원 | I31: 명상/마음챙김 앱 | J31: 명상,마음챙김,스트레스관리 | K31: 수면,불안,번아웃,EAP | L31: Subscription(구독형) | M31: 국내 마음챙김 명상 앱, B2C 구독과 기업 EAP 모델 운영 | N31: 46225 | O31: 46225 | P31: 정신건강|정보제공|개인,기업임직원|명상/마음챙김 앱|Subscription(구독형) | Q31: 1 | R31: 27 | S31: 명상 콘텐츠와 자기관리 중심 서비스로, 중증 정신건강 문제나 전문적인 치료·진단을 대체하기 어려움 | T31: 7일 무료체험 후 정기구독; 월 5,900원, 3개월 17,500원, 6개월 29,000원, 12개월 47,000원; 앱스토어 기준
A32: CP031 | B32: 코끼리 | C32: 정신건강 | D32: 정보제공 | E32: 한국 | F32: 일반경쟁자 | G32: 라이프스타일 | H32: 개인 | I32: 수면/명상 콘텐츠 앱 | J32: 명상,수면,ASMR | K32: 힐링콘텐츠,마음챙김,수면관리 | L32: Freemium(프리미엄) | M32: 국내 수면·명상 콘텐츠 앱, 아토머스가 인수해 마인드카페와 연계 가능 | N32: 46225 | O32: 46225 | P32: 정신건강|정보제공|개인|수면/명상 콘텐츠 앱|Freemium(프리미엄) | Q32: 1 | R32: 28 | S32: 콘텐츠 소비와 자기관리 중심이라 개인별 상담이나 임상적 개입이 부족하며, 유료 콘텐츠 이용을 위해 구독이 필요할 수 있음 | T32: 일부 콘텐츠 무료 제공; 유료 콘텐츠·구독형 이용권 제공; 정확한 최신 요금은 앱 결제 화면 확인 필요
A33: CP032 | B33: 하루콩 | C33: 정신건강 | D33: 데이터기록관리 | E33: 한국 | F33: 카테고리리더 | G33: 라이프스타일 | H33: 개인 | I33: 감정 기록 앱 | J33: 감정기록,무드트래킹,일기 | K33: 감정리포트,습관기록,자가이해 | L33: Freemium(프리미엄) | M33: 블루시그넘의 감정 기록 앱, 감정 데이터를 기반으로 자기이해 지원 | N33: 46225 | O33: 46225 | P33: 정신건강|데이터기록관리|개인|감정 기록 앱|Freemium(프리미엄) | Q33: 1 | R33: 29 | S33: 감정과 활동을 기록하는 데 초점이 있어 기록만으로 문제 해결이나 전문적인 심리 개입까지 이어지기 어려움 | T33: 기본 기록 기능 무료; 일부 기능·콘텐츠의 유료 여부 및 최신 요금은 앱스토어 확인 필요
A34: CP033 | B34: 무디 | C34: 정신건강 | D34: 개입치료 | E34: 한국 | F34: 일반경쟁자 | G34: 라이프스타일 | H34: 개인 | I34: AI 감정 가이드 앱 | J34: 감정관리,AI가이드,심리퀘스트 | K34: 감정태그,트레이닝,스토리콘텐츠 | L34: Freemium(프리미엄) | M34: 블루시그넘의 감정 관리 앱, 감정별 퀘스트와 사고방식 훈련 제공 | N34: 46225 | O34: 46225 | P34: 정신건강|개입치료|개인|AI 감정 가이드 앱|Freemium(프리미엄) | Q34: 1 | R34: 30 | S34: AI가 제공하는 감정 가이드는 전문 상담이나 치료를 대체할 수 없으며, 입력 내용에 따라 추천의 정확도와 적합도가 달라질 수 있음 | T34: 기본 기능 무료 또는 인앱결제 제공; 정확한 유료 기능과 요금은 앱스토어 확인 필요
A35: CP034 | B35: 마인들링 | C35: 정신건강 | D35: 개입치료 | E35: 한국 | F35: 일반경쟁자 | G35: 라이프스타일 | H35: 개인 | I35: 마인드케어 앱 | J35: 마음관리,자가관리,심리콘텐츠 | K35: 맞춤케어,정서관리,스트레스관리 | L35: Subscription(구독형) | M35: 개인 맞춤형 마인드케어 앱으로 분류 가능 | N35: 46225 | O35: 46225 | P35: 정신건강|개입치료|개인|마인드케어 앱|Subscription(구독형) | Q35: 1 | R35: 31 | S35: 자가관리와 콘텐츠 중심 서비스로 위기 상황이나 복합적인 정신건강 문제에 대한 전문적 대응이 제한될 수 있음 | T35: 구독형 서비스로 분류; 월·연 구독료와 무료체험 여부는 최신 앱 결제 화면 확인 필요
A36: CP035 | B36: 디스턴싱 | C36: 정신건강 | D36: 개입치료 | E36: 한국 | F36: 일반경쟁자 | G36: 라이프스타일 | H36: 개인 | I36: 비약물 심리치료 앱 | J36: 심리치료,자가개입,마음관리 | K36: 불안,우울,비약물치료,자가훈련 | L36: Subscription(구독형) | M36: 비약물 심리치료·자가개입형 서비스로 PREP의 개입치료 축 참고 가능 | N36: 46225 | O36: 46225 | P36: 정신건강|개입치료|개인|비약물 심리치료 앱|Subscription(구독형) | Q36: 1 | R36: 32 | S36: 비약물 자가개입 중심이어서 고위험 우울·불안이나 진단·처방이 필요한 이용자에게는 충분하지 않을 수 있음 | T36: 구독형 서비스로 분류; 정확한 월·연 요금은 공개 자료 추가 확인 필요
A37: CP036 | B37: 네이버 엑스퍼트 심리상담 | C37: 정신건강 | D37: 매칭연결 | E37: 한국 | F37: 플랫폼 | G37: 라이프스타일 | H37: 개인 | I37: 전문가 상담 마켓플레이스 | J37: 전문가매칭,온라인상담,심리상담 | K37: 채팅상담,음성상담,영상상담 | L37: Two-sided Market(양면시장) | M37: 네이버 기반 전문가 상담 플랫폼, 심리상담 카테고리 포함 | N37: 46225 | O37: 46225 | P37: 정신건강|매칭연결|개인|전문가 상담 마켓플레이스|Two-sided Market(양면시장) | Q37: 1 | R37: 33 | S37: 대형 플랫폼의 전문가 선택지는 넓지만 상담 품질과 전문성의 편차를 이용자가 직접 판단해야 함 | T37: 상담 전문가·상품별 개별 결제; 채팅·음성·영상 상담 가격은 전문가와 상품에 따라 상이
A38: CP037 | B38: 퍼플웨일 | C38: 정신건강 | D38: 데이터기록관리 | E38: 한국 | F38: 일반경쟁자 | G38: 라이프스타일 | H38: 개인,환자 | I38: 신체화 장애 관리 서비스 | J38: 신체화장애,PHR,정신건강 | K38: 증상기록,자가관리,디지털케어 | L38: Digitization(디지털전환) | M38: 휴레이포지티브 포트폴리오 내 신체화 장애 관리 서비스 | N38: 46225 | O38: 46225 | P38: 정신건강|데이터기록관리|개인,환자|신체화 장애 관리 서비스|Digitization(디지털전환) | Q38: 1 | R38: 34 | S38: 특정 신체화 증상 관리에 초점이 맞춰져 있어 일반적인 정신건강 관리나 다양한 질환으로의 확장성이 제한될 수 있음 | T38: 기관·서비스 계약 기반으로 추정; 개인 이용자용 공개 가격 확인 필요
A39: CP038 | B39: 옴니핏 마인드케어 | C39: 정신건강 | D39: 데이터기록관리 | E39: 한국 | F39: 일반경쟁자 | G39: 생체지표 | H39: 개인,기관 | I39: 스트레스/두뇌건강 측정 솔루션 | J39: 스트레스측정,HRV,뇌파 | K39: 멘탈헬스트래커,생체신호,기관용 | L39: Sensor As A Service(센서서비스) | M39: 생체신호 기반 정신건강 상태 측정 솔루션으로 분류 가능 | N39: 46225 | O39: 46225 | P39: 정신건강|데이터기록관리|개인,기관|스트레스/두뇌건강 측정 솔루션|Sensor As A Service(센서서비스) | Q39: 1 | R39: 35 | S39: 생체신호 측정 결과가 심리 상태를 완전히 설명하지 못하며, 측정 장비와 환경에 따라 결과가 달라질 수 있음 | T39: 기관·기업 대상 솔루션 계약형으로 추정; 장비·구축·이용 범위별 견적형, 공개 가격 미확인
A40: CP039 | B40: 상담 오랑 | C40: 정신건강 | D40: 매칭연결 | E40: 한국 | F40: 일반경쟁자 | G40: 라이프스타일 | H40: 청년 | I40: 청년 마음건강 상담 서비스 | J40: 청년상담,마음건강,공공상담 | K40: 온라인상담,생활상담,1대1상담 | L40: Self-service(셀프서비스) | M40: 민간 기업은 아니지만 국내 청년 대상 마음건강 상담 접근 방식 참고용 | N40: 46225 | O40: 46225 | P40: 정신건강|매칭연결|청년|청년 마음건강 상담 서비스|Self-service(셀프서비스) | Q40: 1 | R40: 36 | S40: 공공 상담 서비스로 대상·지역·운영시간에 제한이 있을 수 있으며, 전문 치료나 지속적인 임상 상담을 대체하지 않음 | T40: 청년 대상 공공 상담; 무료 상담 중심, 이용 조건·운영 지역별 상이
... A53: CP052 | B53: 헬스맥스 | C53: 만성질환 | D53: 데이터기록관리 | E53: 한국 | F53: 일반경쟁자 | G53: 생체지표 | H53: 지자체,기관,개인 | I53: 스마트 건강관리/만성질환 관리 솔루션 | J53: 혈압,혈당,비만관리 | K53: 건강측정,공공헬스케어,원격관리,생활습관 | L53: Digitization(디지털전환) | M53: 공공/기관 중심의 혈압·혈당·비만 등 건강 측정 및 관리 솔루션 | N53: 46225 | O53: 46225 | P53: 만성질환|데이터기록관리|지자체,기관,개인|스마트 건강관리/만성질환 관리 솔루션|Digitization(디지털전환) | Q53: 1 | R53: 49 | S53: 기관·지자체 도입 의존도가 높아 개인 사용자의 접근성이 낮을 수 있으며, 측정 결과만으로 질환 관리 효과를 보장하기 어려움 | T53: 지자체·기관 대상 구축·운영 계약형으로 추정; 장비·플랫폼·운영 범위별 견적, 공개 가격 미확인
A54: CP053 | B54: 꿀잠닥터 | C54: 수면 | D54: 정보제공 | E54: 한국 | F54: 일반경쟁자 | G54: 라이프스타일 | H54: 수면개선희망자 | I54: 앱단독 | J54: 수면 코칭, 수면 일기, 맞춤 루틴 | K54: 콘텐츠 추천, 주간 리포트 | L54: Freemium(프리미엄) | M54: 구글플레이 설명상 수면 연구 데이터 기반 코칭 앱. 개발사/연락처가 한국으로 표기됨. 요금제는 확인 필요. | N54: 46227 | O54: 46241 | P54: =IF(L54="","",C54&"|"&D54&"|"&H54&"|"&I54&"|"&L54) | Q54: =IF(P54="",0,IF(COUNTIF($P$2:P54,P54)=1,1,0)) | R54: =IF(Q54=1,SUM($Q$2:Q54),"") | S54: 사용자 수동 기록(설문·활동) 및 외부 콘텐츠(유튜브·블로그) 추천 중심이라 정밀한 수면 측정이나 전문 의료 진단에는 한계가 있고 다운로드 규모가 적음 | T54: 완전 무료
A55: CP054 | B55: 슬립큐(SleepQ) | C55: 수면 | D55: 개입치료 | E55: 한국 | F55: 카테고리리더 | G55: 라이프스타일 | H55: 불면증환자 | I55: 앱단독 | J55: 디지털치료, 수면습관 교정, 처방 프로그램 | K55: 의사 모니터링, 6주 치료 | L55: Subscription(구독형) | M55: 웰트 개발 불면증 디지털 치료제,디지털 의료기기, 병원 처방 및 비대면 진료 통한 앱 접근이 가능 | N55: 46227 | O55: 46241 | P55: =IF(L55="","",C55&"|"&D55&"|"&H55&"|"&I55&"|"&L55) | Q55: =IF(P55="",0,IF(COUNTIF($P$2:P55,P55)=1,1,0)) | R55: =IF(Q55=1,SUM($Q$2:Q55),"") | S55: 식약처 허가를 받은 전문 디지털 치료기기(DTx)로 의사의 진단 및 처방이 필수적이라 일반 소비자의 자유로운 사용 접근성이 제한됨 | T55: 앱 다운로드는 무료이나, 단 의사처방 인증코드 필요. 처방 프로그램 비용 약 20- 25만원 내외, 실손보험 적용시 실제 부담금 25000원 정도 수준으로 낮아질 수 있음.
A56: CP055 | B56: Nightly(미라클나잇) | C56: 수면 | D56: 정보제공 | E56: 한국 | F56: 일반경쟁자 | G56: 라이프스타일 | H56: 전연령 | I56: 앱단독 | J56: 모노럴비트, 수면 유도, 알람 | K56: 명상, 기상 루틴 | L56: Subscription(구독형) | M56: AI·뇌과학 기반 수면 유도 앱 | N56: 46227 | O56: 46241 | P56: =IF(L56="","",C56&"|"&D56&"|"&H56&"|"&I56&"|"&L56) | Q56: =IF(P56="",0,IF(COUNTIF($P$2:P56,P56)=1,1,0)) | R56: =IF(Q56=1,SUM($Q$2:Q56),"") | S56: 수면 유도 음악·영상·알림 중심으로, 심각한 수면장애의 의학적 해결에는 한계. 콘텐츠 이용을 위해 구독이 필요할 수 있음 | T56: 기본 무료(일부 기능 체험), 1개월 이용권 월 7,700원 / 12개월 이용권 연 77,000원 (정기 자동 결제, 무료 체험 기간 제공)
A57: CP056 | B57: 알라미 | C57: 수면 | D57: 정보제공 | E57: 한국 | F57: 일반경쟁자 | G57: 라이프스타일 | H57: 전연령 | I57: 앱단독 | J57: 알람 미션, 수면 분석, 코골이 체크 | K57: 수면 사운드, 리마인더 | L57: Freemium(프리미엄) | M57: 수면 분석을 제공하는 웰니스 앱, 인앱구매(광고 제거, 프리미엄 기능해제, 일부 고급 수면 분석/알람기능이용) | N57: 46227 | O57: 46241 | P57: =IF(L57="","",C57&"|"&D57&"|"&H57&"|"&I57&"|"&L57) | Q57: =IF(P57="",0,IF(COUNTIF($P$2:P57,P57)=1,1,0)) | R57: =IF(Q57=1,SUM($Q$2:Q57),"") | S57: 기상 알람과 수면 관리 기능 중심이라 전문적인 수면 분석·치료 기능은 제한적. 알람·미션 기능이 일부 사용자에게 피로감을 줄 수 있음 | T57: 기본 무료(광고 포함), 프리미엄 구독 시 월 6,900원 / 연 58,000원 선(광고 제거 및 고급 미션·수면 분석 기능 무제한 이용, Google Play Pass 지원)
A58: CP057 | B58: 에이슬립 | C58: 수면 | D58: 데이터기록관리 | E58: 한국 | F58: 카테고리리더 | G58: 생체지표 | H58: B2B파트너, 개인 | I58: 기기연동 | J58: 수면 단계 분석, 호흡음 분석, 수면 리포트 | K58: API, SDK, 대시보드 | L58: Sensor As A Service(센서서비스) | M58: 수면 AI/SDK/API를 제공하는 한국 슬립테크 서비스 | N58: 46227 | O58: 46241 | P58: =IF(L58="","",C58&"|"&D58&"|"&H58&"|"&I58&"|"&L58) | Q58: =IF(P58="",0,IF(COUNTIF($P$2:P58,P58)=1,1,0)) | R58: =IF(Q58=1,SUM($Q$2:Q58),"") | S58: B2B 파트너 및 수면 측정 솔루션 중심으로 일반 소비자가 단독 이용하기 어려울 수 있음. API·SDK 또는 기기 연동 의존도가 높음 | T58: B2B 전용 서비스로 초기 구축비는 없으며, 기업의 선택 기능(수면 단계·실시간 분석·코골이 등)과 실제 유효 수면 데이터 측정 건수에 따른 종량제 과금 방식임
A59: CP058 | B59: RESTDAWN | C59: 수면 | D59: 정보제공 | E59: 한국 | F59: 일반경쟁자 | G59: 라이프스타일 | H59: 불규칙수면자, 건강관심층 | I59: 앱단독 | J59: 수면 리포트, 루틴 관리, 기록 | K59: 맞춤 분석, 일상 패턴 | L59: Freemium(프리미엄) | M59: 플레이스토어(애플 x), 수면을 데이터로 기록하고 이해하는 리포트 앱 | N59: 46227 | O59: 46241 | P59: =IF(L59="","",C59&"|"&D59&"|"&H59&"|"&I59&"|"&L59) | Q59: =IF(P59="",0,IF(COUNTIF($P$2:P59,P59)=1,1,0)) | R59: =IF(Q59=1,SUM($Q$2:Q59),"") | S59: 수면 리포트와 루틴 관리 중심으로, 생활습관 개선 이상의 의료적 진단·치료에는 한계. 앱 데이터와 사용자의 기록 지속성이 필요 | T59: 기본 무료(광고 포함), 프리미엄 구독 시 월 4,900원 / 연간 할인 제공(AI 수면 코칭, 정밀 패턴 분석 및 맞춤 루틴 무제한 이용, 7일 무료 체험 가능)
A60: CP059 | B60: 삼성헬스 | C60: 수면 | D60: 데이터기록관리 | E60: 한국 | F60: 플랫폼 | G60: 생체지표 | H60: 개인 | I60: 웨어러블연동 | J60: 수면 추적, 수면 단계, 코골이 감지 | K60: 코칭, 스트레스 관리 | L60: Lock-in(락인) | M60: 갤럭시 워치와 연동되는 대표 건강 플랫폼 | N60: 46227 | O60: 46241 | P60: =IF(L60="","",C60&"|"&D60&"|"&H60&"|"&I60&"|"&L60) | Q60: =IF(P60="",0,IF(COUNTIF($P$2:P60,P60)=1,1,0)) | R60: =IF(Q60=1,SUM($Q$2:Q60),"") | S60: 삼성 기기 및 웨어러블 생태계 의존도가 높음. 기기 없이 이용할 경우 수면 측정·분석 기능이 제한될 수 있음 | T60: 기본 앱 무료. 일부 기능은 삼성 웨어러블 등 별도 기기 필요
A61: CP060 | B61: 더헬스(The Health) | C61: 수면 | D61: 데이터기록관리 | E61: 한국 | F61: 일반경쟁자 | G61: 생체지표 | H61: 보험연계 건강관리대상자 | I61: 웨어러블연동 | J61: 수면 측정, 호흡소리 분석, 기상시간 제안 | K61: AI 패턴 분석, 건강플랫폼 연계 | L61: Lock-in(락인) | M61: 건강플랫폼의 수면 측정 기능 | N61: 46227 | O61: 46241 | P61: =IF(L61="","",C61&"|"&D61&"|"&H61&"|"&I61&"|"&L61) | Q61: =IF(P61="",0,IF(COUNTIF($P$2:P61,P61)=1,1,0)) | R61: =IF(Q61=1,SUM($Q$2:Q61),"") | S61: 수면, 운동, 식단, 마음건강 등 다방면의 건강관리를 종합 제공하나 전문 헬스케어 서비스 대비 깊이가 아쉬울 수 있고 보험사 마케팅 및 이벤트 연계 요소가 포함됨 | T61: 완전 무료
...

Sheet bm_mapping
A1: mapping_id | B1: category_1 | C1: category_2 | D1: target | E1: service_type | F1: bm_pattern | G1: frequency_score | H1: frequency_score_global | I1: precedent_level | J1: contributing_competitor_ids | K1: evidence_id | L1: last_computed_at
A2: =IF(B2="","","BM"&TEXT(ROW()-1,"000")) | B2: {=IFERROR(INDEX(competitors!$C$2:$C$101,MATCH(1,competitors!$R$2:$R$101,0)),"")} | C2: {=IFERROR(INDEX(competitors!$D$2:$D$101,MATCH(1,competitors!$R$2:$R$101,0)),"")} | D2: {=IFERROR(INDEX(competitors!$H$2:$H$101,MATCH(1,competitors!$R$2:$R$101,0)),"")} | E2: {=IFERROR(INDEX(competitors!$I$2:$I$101,MATCH(1,competitors!$R$2:$R$101,0)),"")} | F2: {=IFERROR(INDEX(competitors!$L$2:$L$101,MATCH(1,competitors!$R$2:$R$101,0)),"")} | G2: =IF(B2="","",COUNTIFS(competitors!$C$2:$C$101,B2,competitors!$D$2:$D$101,C2,competitors!$H$2:$H$101,D2,competitors!$I$2:$I$101,E2,competitors!$L$2:$L$101,F2,competitors!$E$2:$E$101,"한국")) | H2: =IF(B2="","",COUNTIFS(competitors!$C$2:$C$101,B2,competitors!$D$2:$D$101,C2,competitors!$H$2:$H$101,D2,competitors!$I$2:$I$101,E2,competitors!$L$2:$L$101,F2)) | I2: =IF(B2="","",IF(G2>=5,"많음",IF(G2>=3,"중간",IF(G2>=1,"적음",IF(H2>=1,"가능","어려움"))))) | J2: {=IF(B2="","",TEXTJOIN(", ",TRUE(),IF((competitors!$C$2:$C$101=B2)*(competitors!$D$2:$D$101=C2)*(competitors!$H$2:$H$101=D2)*(competitors!$I$2:$I$101=E2)*(competitors!$L$2:$L$101=F2),competitors!$B$2:$B$101,"")))} | L2: =IF(B2="","",TODAY())
A3: =IF(B3="","","BM"&TEXT(ROW()-1,"000")) | B3: {=IFERROR(INDEX(competitors!$C$2:$C$101,MATCH(2,competitors!$R$2:$R$101,0)),"")} | C3: {=IFERROR(INDEX(competitors!$D$2:$D$101,MATCH(2,competitors!$R$2:$R$101,0)),"")} | D3: {=IFERROR(INDEX(competitors!$H$2:$H$101,MATCH(2,competitors!$R$2:$R$101,0)),"")} | E3: {=IFERROR(INDEX(competitors!$I$2:$I$101,MATCH(2,competitors!$R$2:$R$101,0)),"")} | F3: {=IFERROR(INDEX(competitors!$L$2:$L$101,MATCH(2,competitors!$R$2:$R$101,0)),"")} | G3: =IF(B3="","",COUNTIFS(competitors!$C$2:$C$101,B3,competitors!$D$2:$D$101,C3,competitors!$H$2:$H$101,D3,competitors!$I$2:$I$101,E3,competitors!$L$2:$L$101,F3,competitors!$E$2:$E$101,"한국")) | H3: =IF(B3="","",COUNTIFS(competitors!$C$2:$C$101,B3,competitors!$D$2:$D$101,C3,competitors!$H$2:$H$101,D3,competitors!$I$2:$I$101,E3,competitors!$L$2:$L$101,F3)) | I3: =IF(B3="","",IF(G3>=5,"많음",IF(G3>=3,"중간",IF(G3>=1,"적음",IF(H3>=1,"가능","어려움"))))) | J3: {=IF(B3="","",TEXTJOIN(", ",TRUE(),IF((competitors!$C$2:$C$101=B3)*(competitors!$D$2:$D$101=C3)*(competitors!$H$2:$H$101=D3)*(competitors!$I$2:$I$101=E3)*(competitors!$L$2:$L$101=F3),competitors!$B$2:$B$101,"")))} | L3: =IF(B3="","",TODAY())
A4: =IF(B4="","","BM"&TEXT(ROW()-1,"000")) | B4: {=IFERROR(INDEX(competitors!$C$2:$C$101,MATCH(3,competitors!$R$2:$R$101,0)),"")} | C4: {=IFERROR(INDEX(competitors!$D$2:$D$101,MATCH(3,competitors!$R$2:$R$101,0)),"")} | D4: {=IFERROR(INDEX(competitors!$H$2:$H$101,MATCH(3,competitors!$R$2:$R$101,0)),"")} | E4: {=IFERROR(INDEX(competitors!$I$2:$I$101,MATCH(3,competitors!$R$2:$R$101,0)),"")} | F4: {=IFERROR(INDEX(competitors!$L$2:$L$101,MATCH(3,competitors!$R$2:$R$101,0)),"")} | G4: =IF(B4="","",COUNTIFS(competitors!$C$2:$C$101,B4,competitors!$D$2:$D$101,C4,competitors!$H$2:$H$101,D4,competitors!$I$2:$I$101,E4,competitors!$L$2:$L$101,F4,competitors!$E$2:$E$101,"한국")) | H4: =IF(B4="","",COUNTIFS(competitors!$C$2:$C$101,B4,competitors!$D$2:$D$101,C4,competitors!$H$2:$H$101,D4,competitors!$I$2:$I$101,E4,competitors!$L$2:$L$101,F4)) | I4: =IF(B4="","",IF(G4>=5,"많음",IF(G4>=3,"중간",IF(G4>=1,"적음",IF(H4>=1,"가능","어려움"))))) | J4: {=IF(B4="","",TEXTJOIN(", ",TRUE(),IF((competitors!$C$2:$C$101=B4)*(competitors!$D$2:$D$101=C4)*(competitors!$H$2:$H$101=D4)*(competitors!$I$2:$I$101=E4)*(competitors!$L$2:$L$101=F4),competitors!$B$2:$B$101,"")))} | L4: =IF(B4="","",TODAY())
A5: =IF(B5="","","BM"&TEXT(ROW()-1,"000")) | B5: {=IFERROR(INDEX(competitors!$C$2:$C$101,MATCH(4,competitors!$R$2:$R$101,0)),"")} | C5: {=IFERROR(INDEX(competitors!$D$2:$D$101,MATCH(4,competitors!$R$2:$R$101,0)),"")} | D5: {=IFERROR(INDEX(competitors!$H$2:$H$101,MATCH(4,competitors!$R$2:$R$101,0)),"")} | E5: {=IFERROR(INDEX(competitors!$I$2:$I$101,MATCH(4,competitors!$R$2:$R$101,0)),"")} | F5: {=IFERROR(INDEX(competitors!$L$2:$L$101,MATCH(4,competitors!$R$2:$R$101,0)),"")} | G5: =IF(B5="","",COUNTIFS(competitors!$C$2:$C$101,B5,competitors!$D$2:$D$101,C5,competitors!$H$2:$H$101,D5,competitors!$I$2:$I$101,E5,competitors!$L$2:$L$101,F5,competitors!$E$2:$E$101,"한국")) | H5: =IF(B5="","",COUNTIFS(competitors!$C$2:$C$101,B5,competitors!$D$2:$D$101,C5,competitors!$H$2:$H$101,D5,competitors!$I$2:$I$101,E5,competitors!$L$2:$L$101,F5)) | I5: =IF(B5="","",IF(G5>=5,"많음",IF(G5>=3,"중간",IF(G5>=1,"적음",IF(H5>=1,"가능","어려움"))))) | J5: {=IF(B5="","",TEXTJOIN(", ",TRUE(),IF((competitors!$C$2:$C$101=B5)*(competitors!$D$2:$D$101=C5)*(competitors!$H$2:$H$101=D5)*(competitors!$I$2:$I$101=E5)*(competitors!$L$2:$L$101=F5),competitors!$B$2:$B$101,"")))} | L5: =IF(B5="","",TODAY())
A6: =IF(B6="","","BM"&TEXT(ROW()-1,"000")) | B6: {=IFERROR(INDEX(competitors!$C$2:$C$101,MATCH(5,competitors!$R$2:$R$101,0)),"")} | C6: {=IFERROR(INDEX(competitors!$D$2:$D$101,MATCH(5,competitors!$R$2:$R$101,0)),"")} | D6: {=IFERROR(INDEX(competitors!$H$2:$H$101,MATCH(5,competitors!$R$2:$R$101,0)),"")} | E6: {=IFERROR(INDEX(competitors!$I$2:$I$101,MATCH(5,competitors!$R$2:$R$101,0)),"")} | F6: {=IFERROR(INDEX(competitors!$L$2:$L$101,MATCH(5,competitors!$R$2:$R$101,0)),"")} | G6: =IF(B6="","",COUNTIFS(competitors!$C$2:$C$101,B6,competitors!$D$2:$D$101,C6,competitors!$H$2:$H$101,D6,competitors!$I$2:$I$101,E6,competitors!$L$2:$L$101,F6,competitors!$E$2:$E$101,"한국")) | H6: =IF(B6="","",COUNTIFS(competitors!$C$2:$C$101,B6,competitors!$D$2:$D$101,C6,competitors!$H$2:$H$101,D6,competitors!$I$2:$I$101,E6,competitors!$L$2:$L$101,F6)) | I6: =IF(B6="","",IF(G6>=5,"많음",IF(G6>=3,"중간",IF(G6>=1,"적음",IF(H6>=1,"가능","어려움"))))) | J6: {=IF(B6="","",TEXTJOIN(", ",TRUE(),IF((competitors!$C$2:$C$101=B6)*(competitors!$D$2:$D$101=C6)*(competitors!$H$2:$H$101=D6)*(competitors!$I$2:$I$101=E6)*(competitors!$L$2:$L$101=F6),competitors!$B$2:$B$101,"")))} | L6: =IF(B6="","",TODAY())
A7: =IF(B7="","","BM"&TEXT(ROW()-1,"000")) | B7: {=IFERROR(INDEX(competitors!$C$2:$C$101,MATCH(6,competitors!$R$2:$R$101,0)),"")} | C7: {=IFERROR(INDEX(competitors!$D$2:$D$101,MATCH(6,competitors!$R$2:$R$101,0)),"")} | D7: {=IFERROR(INDEX(competitors!$H$2:$H$101,MATCH(6,competitors!$R$2:$R$101,0)),"")} | E7: {=IFERROR(INDEX(competitors!$I$2:$I$101,MATCH(6,competitors!$R$2:$R$101,0)),"")} | F7: {=IFERROR(INDEX(competitors!$L$2:$L$101,MATCH(6,competitors!$R$2:$R$101,0)),"")} | G7: =IF(B7="","",COUNTIFS(competitors!$C$2:$C$101,B7,competitors!$D$2:$D$101,C7,competitors!$H$2:$H$101,D7,competitors!$I$2:$I$101,E7,competitors!$L$2:$L$101,F7,competitors!$E$2:$E$101,"한국")) | H7: =IF(B7="","",COUNTIFS(competitors!$C$2:$C$101,B7,competitors!$D$2:$D$101,C7,competitors!$H$2:$H$101,D7,competitors!$I$2:$I$101,E7,competitors!$L$2:$L$101,F7)) | I7: =IF(B7="","",IF(G7>=5,"많음",IF(G7>=3,"중간",IF(G7>=1,"적음",IF(H7>=1,"가능","어려움"))))) | J7: {=IF(B7="","",TEXTJOIN(", ",TRUE(),IF((competitors!$C$2:$C$101=B7)*(competitors!$D$2:$D$101=C7)*(competitors!$H$2:$H$101=D7)*(competitors!$I$2:$I$101=E7)*(competitors!$L$2:$L$101=F7),competitors!$B$2:$B$101,"")))} | L7: =IF(B7="","",TODAY())
A8: =IF(B8="","","BM"&TEXT(ROW()-1,"000")) | B8: {=IFERROR(INDEX(competitors!$C$2:$C$101,MATCH(7,competitors!$R$2:$R$101,0)),"")} | C8: {=IFERROR(INDEX(competitors!$D$2:$D$101,MATCH(7,competitors!$R$2:$R$101,0)),"")} | D8: {=IFERROR(INDEX(competitors!$H$2:$H$101,MATCH(7,competitors!$R$2:$R$101,0)),"")} | E8: {=IFERROR(INDEX(competitors!$I$2:$I$101,MATCH(7,competitors!$R$2:$R$101,0)),"")} | F8: {=IFERROR(INDEX(competitors!$L$2:$L$101,MATCH(7,competitors!$R$2:$R$101,0)),"")} | G8: =IF(B8="","",COUNTIFS(competitors!$C$2:$C$101,B8,competitors!$D$2:$D$101,C8,competitors!$H$2:$H$101,D8,competitors!$I$2:$I$101,E8,competitors!$L$2:$L$101,F8,competitors!$E$2:$E$101,"한국")) | H8: =IF(B8="","",COUNTIFS(competitors!$C$2:$C$101,B8,competitors!$D$2:$D$101,C8,competitors!$H$2:$H$101,D8,competitors!$I$2:$I$101,E8,competitors!$L$2:$L$101,F8)) | I8: =IF(B8="","",IF(G8>=5,"많음",IF(G8>=3,"중간",IF(G8>=1,"적음",IF(H8>=1,"가능","어려움"))))) | J8: {=IF(B8="","",TEXTJOIN(", ",TRUE(),IF((competitors!$C$2:$C$101=B8)*(competitors!$D$2:$D$101=C8)*(competitors!$H$2:$H$101=D8)*(competitors!$I$2:$I$101=E8)*(competitors!$L$2:$L$101=F8),competitors!$B$2:$B$101,"")))} | L8: =IF(B8="","",TODAY())
A9: =IF(B9="","","BM"&TEXT(ROW()-1,"000")) | B9: {=IFERROR(INDEX(competitors!$C$2:$C$101,MATCH(8,competitors!$R$2:$R$101,0)),"")} | C9: {=IFERROR(INDEX(competitors!$D$2:$D$101,MATCH(8,competitors!$R$2:$R$101,0)),"")} | D9: {=IFERROR(INDEX(competitors!$H$2:$H$101,MATCH(8,competitors!$R$2:$R$101,0)),"")} | E9: {=IFERROR(INDEX(competitors!$I$2:$I$101,MATCH(8,competitors!$R$2:$R$101,0)),"")} | F9: {=IFERROR(INDEX(competitors!$L$2:$L$101,MATCH(8,competitors!$R$2:$R$101,0)),"")} | G9: =IF(B9="","",COUNTIFS(competitors!$C$2:$C$101,B9,competitors!$D$2:$D$101,C9,competitors!$H$2:$H$101,D9,competitors!$I$2:$I$101,E9,competitors!$L$2:$L$101,F9,competitors!$E$2:$E$101,"한국")) | H9: =IF(B9="","",COUNTIFS(competitors!$C$2:$C$101,B9,competitors!$D$2:$D$101,C9,competitors!$H$2:$H$101,D9,competitors!$I$2:$I$101,E9,competitors!$L$2:$L$101,F9)) | I9: =IF(B9="","",IF(G9>=5,"많음",IF(G9>=3,"중간",IF(G9>=1,"적음",IF(H9>=1,"가능","어려움"))))) | J9: {=IF(B9="","",TEXTJOIN(", ",TRUE(),IF((competitors!$C$2:$C$101=B9)*(competitors!$D$2:$D$101=C9)*(competitors!$H$2:$H$101=D9)*(competitors!$I$2:$I$101=E9)*(competitors!$L$2:$L$101=F9),competitors!$B$2:$B$101,"")))} | L9: =IF(B9="","",TODAY())
A10: =IF(B10="","","BM"&TEXT(ROW()-1,"000")) | B10: {=IFERROR(INDEX(competitors!$C$2:$C$101,MATCH(9,competitors!$R$2:$R$101,0)),"")} | C10: {=IFERROR(INDEX(competitors!$D$2:$D$101,MATCH(9,competitors!$R$2:$R$101,0)),"")} | D10: {=IFERROR(INDEX(competitors!$H$2:$H$101,MATCH(9,competitors!$R$2:$R$101,0)),"")} | E10: {=IFERROR(INDEX(competitors!$I$2:$I$101,MATCH(9,competitors!$R$2:$R$101,0)),"")} | F10: {=IFERROR(INDEX(competitors!$L$2:$L$101,MATCH(9,competitors!$R$2:$R$101,0)),"")} | G10: =IF(B10="","",COUNTIFS(competitors!$C$2:$C$101,B10,competitors!$D$2:$D$101,C10,competitors!$H$2:$H$101,D10,competitors!$I$2:$I$101,E10,competitors!$L$2:$L$101,F10,competitors!$E$2:$E$101,"한국")) | H10: =IF(B10="","",COUNTIFS(competitors!$C$2:$C$101,B10,competitors!$D$2:$D$101,C10,competitors!$H$2:$H$101,D10,competitors!$I$2:$I$101,E10,competitors!$L$2:$L$101,F10)) | I10: =IF(B10="","",IF(G10>=5,"많음",IF(G10>=3,"중간",IF(G10>=1,"적음",IF(H10>=1,"가능","어려움"))))) | J10: {=IF(B10="","",TEXTJOIN(", ",TRUE(),IF((competitors!$C$2:$C$101=B10)*(competitors!$D$2:$D$101=C10)*(competitors!$H$2:$H$101=D10)*(competitors!$I$2:$I$101=E10)*(competitors!$L$2:$L$101=F10),competitors!$B$2:$B$101,"")))} | L10: =IF(B10="","",TODAY())
A11: =IF(B11="","","BM"&TEXT(ROW()-1,"000")) | B11: {=IFERROR(INDEX(competitors!$C$2:$C$101,MATCH(10,competitors!$R$2:$R$101,0)),"")} | C11: {=IFERROR(INDEX(competitors!$D$2:$D$101,MATCH(10,competitors!$R$2:$R$101,0)),"")} | D11: {=IFERROR(INDEX(competitors!$H$2:$H$101,MATCH(10,competitors!$R$2:$R$101,0)),"")} | E11: {=IFERROR(INDEX(competitors!$I$2:$I$101,MATCH(10,competitors!$R$2:$R$101,0)),"")} | F11: {=IFERROR(INDEX(competitors!$L$2:$L$101,MATCH(10,competitors!$R$2:$R$101,0)),"")} | G11: =IF(B11="","",COUNTIFS(competitors!$C$2:$C$101,B11,competitors!$D$2:$D$101,C11,competitors!$H$2:$H$101,D11,competitors!$I$2:$I$101,E11,competitors!$L$2:$L$101,F11,competitors!$E$2:$E$101,"한국")) | H11: =IF(B11="","",COUNTIFS(competitors!$C$2:$C$101,B11,competitors!$D$2:$D$101,C11,competitors!$H$2:$H$101,D11,competitors!$I$2:$I$101,E11,competitors!$L$2:$L$101,F11)) | I11: =IF(B11="","",IF(G11>=5,"많음",IF(G11>=3,"중간",IF(G11>=1,"적음",IF(H11>=1,"가능","어려움"))))) | J11: {=IF(B11="","",TEXTJOIN(", ",TRUE(),IF((competitors!$C$2:$C$101=B11)*(competitors!$D$2:$D$101=C11)*(competitors!$H$2:$H$101=D11)*(competitors!$I$2:$I$101=E11)*(competitors!$L$2:$L$101=F11),competitors!$B$2:$B$101,"")))} | L11: =IF(B11="","",TODAY())
A12: =IF(B12="","","BM"&TEXT(ROW()-1,"000")) | B12: {=IFERROR(INDEX(competitors!$C$2:$C$101,MATCH(11,competitors!$R$2:$R$101,0)),"")} | C12: {=IFERROR(INDEX(competitors!$D$2:$D$101,MATCH(11,competitors!$R$2:$R$101,0)),"")} | D12: {=IFERROR(INDEX(competitors!$H$2:$H$101,MATCH(11,competitors!$R$2:$R$101,0)),"")} | E12: {=IFERROR(INDEX(competitors!$I$2:$I$101,MATCH(11,competitors!$R$2:$R$101,0)),"")} | F12: {=IFERROR(INDEX(competitors!$L$2:$L$101,MATCH(11,competitors!$R$2:$R$101,0)),"")} | G12: =IF(B12="","",COUNTIFS(competitors!$C$2:$C$101,B12,competitors!$D$2:$D$101,C12,competitors!$H$2:$H$101,D12,competitors!$I$2:$I$101,E12,competitors!$L$2:$L$101,F12,competitors!$E$2:$E$101,"한국")) | H12: =IF(B12="","",COUNTIFS(competitors!$C$2:$C$101,B12,competitors!$D$2:$D$101,C12,competitors!$H$2:$H$101,D12,competitors!$I$2:$I$101,E12,competitors!$L$2:$L$101,F12)) | I12: =IF(B12="","",IF(G12>=5,"많음",IF(G12>=3,"중간",IF(G12>=1,"적음",IF(H12>=1,"가능","어려움"))))) | J12: {=IF(B12="","",TEXTJOIN(", ",TRUE(),IF((competitors!$C$2:$C$101=B12)*(competitors!$D$2:$D$101=C12)*(competitors!$H$2:$H$101=D12)*(competitors!$I$2:$I$101=E12)*(competitors!$L$2:$L$101=F12),competitors!$B$2:$B$101,"")))} | L12: =IF(B12="","",TODAY())
A13: =IF(B13="","","BM"&TEXT(ROW()-1,"000")) | B13: {=IFERROR(INDEX(competitors!$C$2:$C$101,MATCH(12,competitors!$R$2:$R$101,0)),"")} | C13: {=IFERROR(INDEX(competitors!$D$2:$D$101,MATCH(12,competitors!$R$2:$R$101,0)),"")} | D13: {=IFERROR(INDEX(competitors!$H$2:$H$101,MATCH(12,competitors!$R$2:$R$101,0)),"")} | E13: {=IFERROR(INDEX(competitors!$I$2:$I$101,MATCH(12,competitors!$R$2:$R$101,0)),"")} | F13: {=IFERROR(INDEX(competitors!$L$2:$L$101,MATCH(12,competitors!$R$2:$R$101,0)),"")} | G13: =IF(B13="","",COUNTIFS(competitors!$C$2:$C$101,B13,competitors!$D$2:$D$101,C13,competitors!$H$2:$H$101,D13,competitors!$I$2:$I$101,E13,competitors!$L$2:$L$101,F13,competitors!$E$2:$E$101,"한국")) | H13: =IF(B13="","",COUNTIFS(competitors!$C$2:$C$101,B13,competitors!$D$2:$D$101,C13,competitors!$H$2:$H$101,D13,competitors!$I$2:$I$101,E13,competitors!$L$2:$L$101,F13)) | I13: =IF(B13="","",IF(G13>=5,"많음",IF(G13>=3,"중간",IF(G13>=1,"적음",IF(H13>=1,"가능","어려움"))))) | J13: {=IF(B13="","",TEXTJOIN(", ",TRUE(),IF((competitors!$C$2:$C$101=B13)*(competitors!$D$2:$D$101=C13)*(competitors!$H$2:$H$101=D13)*(competitors!$I$2:$I$101=E13)*(competitors!$L$2:$L$101=F13),competitors!$B$2:$B$101,"")))} | L13: =IF(B13="","",TODAY())
A14: =IF(B14="","","BM"&TEXT(ROW()-1,"000")) | B14: {=IFERROR(INDEX(competitors!$C$2:$C$101,MATCH(13,competitors!$R$2:$R$101,0)),"")} | C14: {=IFERROR(INDEX(competitors!$D$2:$D$101,MATCH(13,competitors!$R$2:$R$101,0)),"")} | D14: {=IFERROR(INDEX(competitors!$H$2:$H$101,MATCH(13,competitors!$R$2:$R$101,0)),"")} | E14: {=IFERROR(INDEX(competitors!$I$2:$I$101,MATCH(13,competitors!$R$2:$R$101,0)),"")} | F14: {=IFERROR(INDEX(competitors!$L$2:$L$101,MATCH(13,competitors!$R$2:$R$101,0)),"")} | G14: =IF(B14="","",COUNTIFS(competitors!$C$2:$C$101,B14,competitors!$D$2:$D$101,C14,competitors!$H$2:$H$101,D14,competitors!$I$2:$I$101,E14,competitors!$L$2:$L$101,F14,competitors!$E$2:$E$101,"한국")) | H14: =IF(B14="","",COUNTIFS(competitors!$C$2:$C$101,B14,competitors!$D$2:$D$101,C14,competitors!$H$2:$H$101,D14,competitors!$I$2:$I$101,E14,competitors!$L$2:$L$101,F14)) | I14: =IF(B14="","",IF(G14>=5,"많음",IF(G14>=3,"중간",IF(G14>=1,"적음",IF(H14>=1,"가능","어려움"))))) | J14: {=IF(B14="","",TEXTJOIN(", ",TRUE(),IF((competitors!$C$2:$C$101=B14)*(competitors!$D$2:$D$101=C14)*(competitors!$H$2:$H$101=D14)*(competitors!$I$2:$I$101=E14)*(competitors!$L$2:$L$101=F14),competitors!$B$2:$B$101,"")))} | L14: =IF(B14="","",TODAY())
A15: =IF(B15="","","BM"&TEXT(ROW()-1,"000")) | B15: {=IFERROR(INDEX(competitors!$C$2:$C$101,MATCH(14,competitors!$R$2:$R$101,0)),"")} | C15: {=IFERROR(INDEX(competitors!$D$2:$D$101,MATCH(14,competitors!$R$2:$R$101,0)),"")} | D15: {=IFERROR(INDEX(competitors!$H$2:$H$101,MATCH(14,competitors!$R$2:$R$101,0)),"")} | E15: {=IFERROR(INDEX(competitors!$I$2:$I$101,MATCH(14,competitors!$R$2:$R$101,0)),"")} | F15: {=IFERROR(INDEX(competitors!$L$2:$L$101,MATCH(14,competitors!$R$2:$R$101,0)),"")} | G15: =IF(B15="","",COUNTIFS(competitors!$C$2:$C$101,B15,competitors!$D$2:$D$101,C15,competitors!$H$2:$H$101,D15,competitors!$I$2:$I$101,E15,competitors!$L$2:$L$101,F15,competitors!$E$2:$E$101,"한국")) | H15: =IF(B15="","",COUNTIFS(competitors!$C$2:$C$101,B15,competitors!$D$2:$D$101,C15,competitors!$H$2:$H$101,D15,competitors!$I$2:$I$101,E15,competitors!$L$2:$L$101,F15)) | I15: =IF(B15="","",IF(G15>=5,"많음",IF(G15>=3,"중간",IF(G15>=1,"적음",IF(H15>=1,"가능","어려움"))))) | J15: {=IF(B15="","",TEXTJOIN(", ",TRUE(),IF((competitors!$C$2:$C$101=B15)*(competitors!$D$2:$D$101=C15)*(competitors!$H$2:$H$101=D15)*(competitors!$I$2:$I$101=E15)*(competitors!$L$2:$L$101=F15),competitors!$B$2:$B$101,"")))} | L15: =IF(B15="","",TODAY())
A16: =IF(B16="","","BM"&TEXT(ROW()-1,"000")) | B16: {=IFERROR(INDEX(competitors!$C$2:$C$101,MATCH(15,competitors!$R$2:$R$101,0)),"")} | C16: {=IFERROR(INDEX(competitors!$D$2:$D$101,MATCH(15,competitors!$R$2:$R$101,0)),"")} | D16: {=IFERROR(INDEX(competitors!$H$2:$H$101,MATCH(15,competitors!$R$2:$R$101,0)),"")} | E16: {=IFERROR(INDEX(competitors!$I$2:$I$101,MATCH(15,competitors!$R$2:$R$101,0)),"")} | F16: {=IFERROR(INDEX(competitors!$L$2:$L$101,MATCH(15,competitors!$R$2:$R$101,0)),"")} | G16: =IF(B16="","",COUNTIFS(competitors!$C$2:$C$101,B16,competitors!$D$2:$D$101,C16,competitors!$H$2:$H$101,D16,competitors!$I$2:$I$101,E16,competitors!$L$2:$L$101,F16,competitors!$E$2:$E$101,"한국")) | H16: =IF(B16="","",COUNTIFS(competitors!$C$2:$C$101,B16,competitors!$D$2:$D$101,C16,competitors!$H$2:$H$101,D16,competitors!$I$2:$I$101,E16,competitors!$L$2:$L$101,F16)) | I16: =IF(B16="","",IF(G16>=5,"많음",IF(G16>=3,"중간",IF(G16>=1,"적음",IF(H16>=1,"가능","어려움"))))) | J16: {=IF(B16="","",TEXTJOIN(", ",TRUE(),IF((competitors!$C$2:$C$101=B16)*(competitors!$D$2:$D$101=C16)*(competitors!$H$2:$H$101=D16)*(competitors!$I$2:$I$101=E16)*(competitors!$L$2:$L$101=F16),competitors!$B$2:$B$101,"")))} | L16: =IF(B16="","",TODAY())
A17: =IF(B17="","","BM"&TEXT(ROW()-1,"000")) | B17: {=IFERROR(INDEX(competitors!$C$2:$C$101,MATCH(16,competitors!$R$2:$R$101,0)),"")} | C17: {=IFERROR(INDEX(competitors!$D$2:$D$101,MATCH(16,competitors!$R$2:$R$101,0)),"")} | D17: {=IFERROR(INDEX(competitors!$H$2:$H$101,MATCH(16,competitors!$R$2:$R$101,0)),"")} | E17: {=IFERROR(INDEX(competitors!$I$2:$I$101,MATCH(16,competitors!$R$2:$R$101,0)),"")} | F17: {=IFERROR(INDEX(competitors!$L$2:$L$101,MATCH(16,competitors!$R$2:$R$101,0)),"")} | G17: =IF(B17="","",COUNTIFS(competitors!$C$2:$C$101,B17,competitors!$D$2:$D$101,C17,competitors!$H$2:$H$101,D17,competitors!$I$2:$I$101,E17,competitors!$L$2:$L$101,F17,competitors!$E$2:$E$101,"한국")) | H17: =IF(B17="","",COUNTIFS(competitors!$C$2:$C$101,B17,competitors!$D$2:$D$101,C17,competitors!$H$2:$H$101,D17,competitors!$I$2:$I$101,E17,competitors!$L$2:$L$101,F17)) | I17: =IF(B17="","",IF(G17>=5,"많음",IF(G17>=3,"중간",IF(G17>=1,"적음",IF(H17>=1,"가능","어려움"))))) | J17: {=IF(B17="","",TEXTJOIN(", ",TRUE(),IF((competitors!$C$2:$C$101=B17)*(competitors!$D$2:$D$101=C17)*(competitors!$H$2:$H$101=D17)*(competitors!$I$2:$I$101=E17)*(competitors!$L$2:$L$101=F17),competitors!$B$2:$B$101,"")))} | L17: =IF(B17="","",TODAY())
A18: =IF(B18="","","BM"&TEXT(ROW()-1,"000")) | B18: {=IFERROR(INDEX(competitors!$C$2:$C$101,MATCH(17,competitors!$R$2:$R$101,0)),"")} | C18: {=IFERROR(INDEX(competitors!$D$2:$D$101,MATCH(17,competitors!$R$2:$R$101,0)),"")} | D18: {=IFERROR(INDEX(competitors!$H$2:$H$101,MATCH(17,competitors!$R$2:$R$101,0)),"")} | E18: {=IFERROR(INDEX(competitors!$I$2:$I$101,MATCH(17,competitors!$R$2:$R$101,0)),"")} | F18: {=IFERROR(INDEX(competitors!$L$2:$L$101,MATCH(17,competitors!$R$2:$R$101,0)),"")} | G18: =IF(B18="","",COUNTIFS(competitors!$C$2:$C$101,B18,competitors!$D$2:$D$101,C18,competitors!$H$2:$H$101,D18,competitors!$I$2:$I$101,E18,competitors!$L$2:$L$101,F18,competitors!$E$2:$E$101,"한국")) | H18: =IF(B18="","",COUNTIFS(competitors!$C$2:$C$101,B18,competitors!$D$2:$D$101,C18,competitors!$H$2:$H$101,D18,competitors!$I$2:$I$101,E18,competitors!$L$2:$L$101,F18)) | I18: =IF(B18="","",IF(G18>=5,"많음",IF(G18>=3,"중간",IF(G18>=1,"적음",IF(H18>=1,"가능","어려움"))))) | J18: {=IF(B18="","",TEXTJOIN(", ",TRUE(),IF((competitors!$C$2:$C$101=B18)*(competitors!$D$2:$D$101=C18)*(competitors!$H$2:$H$101=D18)*(competitors!$I$2:$I$101=E18)*(competitors!$L$2:$L$101=F18),competitors!$B$2:$B$101,"")))} | L18: =IF(B18="","",TODAY())
A19: =IF(B19="","","BM"&TEXT(ROW()-1,"000")) | B19: {=IFERROR(INDEX(competitors!$C$2:$C$101,MATCH(18,competitors!$R$2:$R$101,0)),"")} | C19: {=IFERROR(INDEX(competitors!$D$2:$D$101,MATCH(18,competitors!$R$2:$R$101,0)),"")} | D19: {=IFERROR(INDEX(competitors!$H$2:$H$101,MATCH(18,competitors!$R$2:$R$101,0)),"")} | E19: {=IFERROR(INDEX(competitors!$I$2:$I$101,MATCH(18,competitors!$R$2:$R$101,0)),"")} | F19: {=IFERROR(INDEX(competitors!$L$2:$L$101,MATCH(18,competitors!$R$2:$R$101,0)),"")} | G19: =IF(B19="","",COUNTIFS(competitors!$C$2:$C$101,B19,competitors!$D$2:$D$101,C19,competitors!$H$2:$H$101,D19,competitors!$I$2:$I$101,E19,competitors!$L$2:$L$101,F19,competitors!$E$2:$E$101,"한국")) | H19: =IF(B19="","",COUNTIFS(competitors!$C$2:$C$101,B19,competitors!$D$2:$D$101,C19,competitors!$H$2:$H$101,D19,competitors!$I$2:$I$101,E19,competitors!$L$2:$L$101,F19)) | I19: =IF(B19="","",IF(G19>=5,"많음",IF(G19>=3,"중간",IF(G19>=1,"적음",IF(H19>=1,"가능","어려움"))))) | J19: {=IF(B19="","",TEXTJOIN(", ",TRUE(),IF((competitors!$C$2:$C$101=B19)*(competitors!$D$2:$D$101=C19)*(competitors!$H$2:$H$101=D19)*(competitors!$I$2:$I$101=E19)*(competitors!$L$2:$L$101=F19),competitors!$B$2:$B$101,"")))} | L19: =IF(B19="","",TODAY())
A20: =IF(B20="","","BM"&TEXT(ROW()-1,"000")) | B20: {=IFERROR(INDEX(competitors!$C$2:$C$101,MATCH(19,competitors!$R$2:$R$101,0)),"")} | C20: {=IFERROR(INDEX(competitors!$D$2:$D$101,MATCH(19,competitors!$R$2:$R$101,0)),"")} | D20: {=IFERROR(INDEX(competitors!$H$2:$H$101,MATCH(19,competitors!$R$2:$R$101,0)),"")} | E20: {=IFERROR(INDEX(competitors!$I$2:$I$101,MATCH(19,competitors!$R$2:$R$101,0)),"")} | F20: {=IFERROR(INDEX(competitors!$L$2:$L$101,MATCH(19,competitors!$R$2:$R$101,0)),"")} | G20: =IF(B20="","",COUNTIFS(competitors!$C$2:$C$101,B20,competitors!$D$2:$D$101,C20,competitors!$H$2:$H$101,D20,competitors!$I$2:$I$101,E20,competitors!$L$2:$L$101,F20,competitors!$E$2:$E$101,"한국")) | H20: =IF(B20="","",COUNTIFS(competitors!$C$2:$C$101,B20,competitors!$D$2:$D$101,C20,competitors!$H$2:$H$101,D20,competitors!$I$2:$I$101,E20,competitors!$L$2:$L$101,F20)) | I20: =IF(B20="","",IF(G20>=5,"많음",IF(G20>=3,"중간",IF(G20>=1,"적음",IF(H20>=1,"가능","어려움"))))) | J20: {=IF(B20="","",TEXTJOIN(", ",TRUE(),IF((competitors!$C$2:$C$101=B20)*(competitors!$D$2:$D$101=C20)*(competitors!$H$2:$H$101=D20)*(competitors!$I$2:$I$101=E20)*(competitors!$L$2:$L$101=F20),competitors!$B$2:$B$101,"")))} | L20: =IF(B20="","",TODAY())
A21: =IF(B21="","","BM"&TEXT(ROW()-1,"000")) | B21: {=IFERROR(INDEX(competitors!$C$2:$C$101,MATCH(20,competitors!$R$2:$R$101,0)),"")} | C21: {=IFERROR(INDEX(competitors!$D$2:$D$101,MATCH(20,competitors!$R$2:$R$101,0)),"")} | D21: {=IFERROR(INDEX(competitors!$H$2:$H$101,MATCH(20,competitors!$R$2:$R$101,0)),"")} | E21: {=IFERROR(INDEX(competitors!$I$2:$I$101,MATCH(20,competitors!$R$2:$R$101,0)),"")} | F21: {=IFERROR(INDEX(competitors!$L$2:$L$101,MATCH(20,competitors!$R$2:$R$101,0)),"")} | G21: =IF(B21="","",COUNTIFS(competitors!$C$2:$C$101,B21,competitors!$D$2:$D$101,C21,competitors!$H$2:$H$101,D21,competitors!$I$2:$I$101,E21,competitors!$L$2:$L$101,F21,competitors!$E$2:$E$101,"한국")) | H21: =IF(B21="","",COUNTIFS(competitors!$C$2:$C$101,B21,competitors!$D$2:$D$101,C21,competitors!$H$2:$H$101,D21,competitors!$I$2:$I$101,E21,competitors!$L$2:$L$101,F21)) | I21: =IF(B21="","",IF(G21>=5,"많음",IF(G21>=3,"중간",IF(G21>=1,"적음",IF(H21>=1,"가능","어려움"))))) | J21: {=IF(B21="","",TEXTJOIN(", ",TRUE(),IF((competitors!$C$2:$C$101=B21)*(competitors!$D$2:$D$101=C21)*(competitors!$H$2:$H$101=D21)*(competitors!$I$2:$I$101=E21)*(competitors!$L$2:$L$101=F21),competitors!$B$2:$B$101,"")))} | L21: =IF(B21="","",TODAY())
A22: =IF(B22="","","BM"&TEXT(ROW()-1,"000")) | B22: {=IFERROR(INDEX(competitors!$C$2:$C$101,MATCH(21,competitors!$R$2:$R$101,0)),"")} | C22: {=IFERROR(INDEX(competitors!$D$2:$D$101,MATCH(21,competitors!$R$2:$R$101,0)),"")} | D22: {=IFERROR(INDEX(competitors!$H$2:$H$101,MATCH(21,competitors!$R$2:$R$101,0)),"")} | E22: {=IFERROR(INDEX(competitors!$I$2:$I$101,MATCH(21,competitors!$R$2:$R$101,0)),"")} | F22: {=IFERROR(INDEX(competitors!$L$2:$L$101,MATCH(21,competitors!$R$2:$R$101,0)),"")} | G22: =IF(B22="","",COUNTIFS(competitors!$C$2:$C$101,B22,competitors!$D$2:$D$101,C22,competitors!$H$2:$H$101,D22,competitors!$I$2:$I$101,E22,competitors!$L$2:$L$101,F22,competitors!$E$2:$E$101,"한국")) | H22: =IF(B22="","",COUNTIFS(competitors!$C$2:$C$101,B22,competitors!$D$2:$D$101,C22,competitors!$H$2:$H$101,D22,competitors!$I$2:$I$101,E22,competitors!$L$2:$L$101,F22)) | I22: =IF(B22="","",IF(G22>=5,"많음",IF(G22>=3,"중간",IF(G22>=1,"적음",IF(H22>=1,"가능","어려움"))))) | J22: {=IF(B22="","",TEXTJOIN(", ",TRUE(),IF((competitors!$C$2:$C$101=B22)*(competitors!$D$2:$D$101=C22)*(competitors!$H$2:$H$101=D22)*(competitors!$I$2:$I$101=E22)*(competitors!$L$2:$L$101=F22),competitors!$B$2:$B$101,"")))} | L22: =IF(B22="","",TODAY())
A23: =IF(B23="","","BM"&TEXT(ROW()-1,"000")) | B23: {=IFERROR(INDEX(competitors!$C$2:$C$101,MATCH(22,competitors!$R$2:$R$101,0)),"")} | C23: {=IFERROR(INDEX(competitors!$D$2:$D$101,MATCH(22,competitors!$R$2:$R$101,0)),"")} | D23: {=IFERROR(INDEX(competitors!$H$2:$H$101,MATCH(22,competitors!$R$2:$R$101,0)),"")} | E23: {=IFERROR(INDEX(competitors!$I$2:$I$101,MATCH(22,competitors!$R$2:$R$101,0)),"")} | F23: {=IFERROR(INDEX(competitors!$L$2:$L$101,MATCH(22,competitors!$R$2:$R$101,0)),"")} | G23: =IF(B23="","",COUNTIFS(competitors!$C$2:$C$101,B23,competitors!$D$2:$D$101,C23,competitors!$H$2:$H$101,D23,competitors!$I$2:$I$101,E23,competitors!$L$2:$L$101,F23,competitors!$E$2:$E$101,"한국")) | H23: =IF(B23="","",COUNTIFS(competitors!$C$2:$C$101,B23,competitors!$D$2:$D$101,C23,competitors!$H$2:$H$101,D23,competitors!$I$2:$I$101,E23,competitors!$L$2:$L$101,F23)) | I23: =IF(B23="","",IF(G23>=5,"많음",IF(G23>=3,"중간",IF(G23>=1,"적음",IF(H23>=1,"가능","어려움"))))) | J23: {=IF(B23="","",TEXTJOIN(", ",TRUE(),IF((competitors!$C$2:$C$101=B23)*(competitors!$D$2:$D$101=C23)*(competitors!$H$2:$H$101=D23)*(competitors!$I$2:$I$101=E23)*(competitors!$L$2:$L$101=F23),competitors!$B$2:$B$101,"")))} | L23: =IF(B23="","",TODAY())
A24: =IF(B24="","","BM"&TEXT(ROW()-1,"000")) | B24: {=IFERROR(INDEX(competitors!$C$2:$C$101,MATCH(23,competitors!$R$2:$R$101,0)),"")} | C24: {=IFERROR(INDEX(competitors!$D$2:$D$101,MATCH(23,competitors!$R$2:$R$101,0)),"")} | D24: {=IFERROR(INDEX(competitors!$H$2:$H$101,MATCH(23,competitors!$R$2:$R$101,0)),"")} | E24: {=IFERROR(INDEX(competitors!$I$2:$I$101,MATCH(23,competitors!$R$2:$R$101,0)),"")} | F24: {=IFERROR(INDEX(competitors!$L$2:$L$101,MATCH(23,competitors!$R$2:$R$101,0)),"")} | G24: =IF(B24="","",COUNTIFS(competitors!$C$2:$C$101,B24,competitors!$D$2:$D$101,C24,competitors!$H$2:$H$101,D24,competitors!$I$2:$I$101,E24,competitors!$L$2:$L$101,F24,competitors!$E$2:$E$101,"한국")) | H24: =IF(B24="","",COUNTIFS(competitors!$C$2:$C$101,B24,competitors!$D$2:$D$101,C24,competitors!$H$2:$H$101,D24,competitors!$I$2:$I$101,E24,competitors!$L$2:$L$101,F24)) | I24: =IF(B24="","",IF(G24>=5,"많음",IF(G24>=3,"중간",IF(G24>=1,"적음",IF(H24>=1,"가능","어려움"))))) | J24: {=IF(B24="","",TEXTJOIN(", ",TRUE(),IF((competitors!$C$2:$C$101=B24)*(competitors!$D$2:$D$101=C24)*(competitors!$H$2:$H$101=D24)*(competitors!$I$2:$I$101=E24)*(competitors!$L$2:$L$101=F24),competitors!$B$2:$B$101,"")))} | L24: =IF(B24="","",TODAY())
A25: =IF(B25="","","BM"&TEXT(ROW()-1,"000")) | B25: {=IFERROR(INDEX(competitors!$C$2:$C$101,MATCH(24,competitors!$R$2:$R$101,0)),"")} | C25: {=IFERROR(INDEX(competitors!$D$2:$D$101,MATCH(24,competitors!$R$2:$R$101,0)),"")} | D25: {=IFERROR(INDEX(competitors!$H$2:$H$101,MATCH(24,competitors!$R$2:$R$101,0)),"")} | E25: {=IFERROR(INDEX(competitors!$I$2:$I$101,MATCH(24,competitors!$R$2:$R$101,0)),"")} | F25: {=IFERROR(INDEX(competitors!$L$2:$L$101,MATCH(24,competitors!$R$2:$R$101,0)),"")} | G25: =IF(B25="","",COUNTIFS(competitors!$C$2:$C$101,B25,competitors!$D$2:$D$101,C25,competitors!$H$2:$H$101,D25,competitors!$I$2:$I$101,E25,competitors!$L$2:$L$101,F25,competitors!$E$2:$E$101,"한국")) | H25: =IF(B25="","",COUNTIFS(competitors!$C$2:$C$101,B25,competitors!$D$2:$D$101,C25,competitors!$H$2:$H$101,D25,competitors!$I$2:$I$101,E25,competitors!$L$2:$L$101,F25)) | I25: =IF(B25="","",IF(G25>=5,"많음",IF(G25>=3,"중간",IF(G25>=1,"적음",IF(H25>=1,"가능","어려움"))))) | J25: {=IF(B25="","",TEXTJOIN(", ",TRUE(),IF((competitors!$C$2:$C$101=B25)*(competitors!$D$2:$D$101=C25)*(competitors!$H$2:$H$101=D25)*(competitors!$I$2:$I$101=E25)*(competitors!$L$2:$L$101=F25),competitors!$B$2:$B$101,"")))} | L25: =IF(B25="","",TODAY())
A26: =IF(B26="","","BM"&TEXT(ROW()-1,"000")) | B26: {=IFERROR(INDEX(competitors!$C$2:$C$101,MATCH(25,competitors!$R$2:$R$101,0)),"")} | C26: {=IFERROR(INDEX(competitors!$D$2:$D$101,MATCH(25,competitors!$R$2:$R$101,0)),"")} | D26: {=IFERROR(INDEX(competitors!$H$2:$H$101,MATCH(25,competitors!$R$2:$R$101,0)),"")} | E26: {=IFERROR(INDEX(competitors!$I$2:$I$101,MATCH(25,competitors!$R$2:$R$101,0)),"")} | F26: {=IFERROR(INDEX(competitors!$L$2:$L$101,MATCH(25,competitors!$R$2:$R$101,0)),"")} | G26: =IF(B26="","",COUNTIFS(competitors!$C$2:$C$101,B26,competitors!$D$2:$D$101,C26,competitors!$H$2:$H$101,D26,competitors!$I$2:$I$101,E26,competitors!$L$2:$L$101,F26,competitors!$E$2:$E$101,"한국")) | H26: =IF(B26="","",COUNTIFS(competitors!$C$2:$C$101,B26,competitors!$D$2:$D$101,C26,competitors!$H$2:$H$101,D26,competitors!$I$2:$I$101,E26,competitors!$L$2:$L$101,F26)) | I26: =IF(B26="","",IF(G26>=5,"많음",IF(G26>=3,"중간",IF(G26>=1,"적음",IF(H26>=1,"가능","어려움"))))) | J26: {=IF(B26="","",TEXTJOIN(", ",TRUE(),IF((competitors!$C$2:$C$101=B26)*(competitors!$D$2:$D$101=C26)*(competitors!$H$2:$H$101=D26)*(competitors!$I$2:$I$101=E26)*(competitors!$L$2:$L$101=F26),competitors!$B$2:$B$101,"")))} | L26: =IF(B26="","",TODAY())
A27: =IF(B27="","","BM"&TEXT(ROW()-1,"000")) | B27: {=IFERROR(INDEX(competitors!$C$2:$C$101,MATCH(26,competitors!$R$2:$R$101,0)),"")} | C27: {=IFERROR(INDEX(competitors!$D$2:$D$101,MATCH(26,competitors!$R$2:$R$101,0)),"")} | D27: {=IFERROR(INDEX(competitors!$H$2:$H$101,MATCH(26,competitors!$R$2:$R$101,0)),"")} | E27: {=IFERROR(INDEX(competitors!$I$2:$I$101,MATCH(26,competitors!$R$2:$R$101,0)),"")} | F27: {=IFERROR(INDEX(competitors!$L$2:$L$101,MATCH(26,competitors!$R$2:$R$101,0)),"")} | G27: =IF(B27="","",COUNTIFS(competitors!$C$2:$C$101,B27,competitors!$D$2:$D$101,C27,competitors!$H$2:$H$101,D27,competitors!$I$2:$I$101,E27,competitors!$L$2:$L$101,F27,competitors!$E$2:$E$101,"한국")) | H27: =IF(B27="","",COUNTIFS(competitors!$C$2:$C$101,B27,competitors!$D$2:$D$101,C27,competitors!$H$2:$H$101,D27,competitors!$I$2:$I$101,E27,competitors!$L$2:$L$101,F27)) | I27: =IF(B27="","",IF(G27>=5,"많음",IF(G27>=3,"중간",IF(G27>=1,"적음",IF(H27>=1,"가능","어려움"))))) | J27: {=IF(B27="","",TEXTJOIN(", ",TRUE(),IF((competitors!$C$2:$C$101=B27)*(competitors!$D$2:$D$101=C27)*(competitors!$H$2:$H$101=D27)*(competitors!$I$2:$I$101=E27)*(competitors!$L$2:$L$101=F27),competitors!$B$2:$B$101,"")))} | L27: =IF(B27="","",TODAY())
A28: =IF(B28="","","BM"&TEXT(ROW()-1,"000")) | B28: {=IFERROR(INDEX(competitors!$C$2:$C$101,MATCH(27,competitors!$R$2:$R$101,0)),"")} | C28: {=IFERROR(INDEX(competitors!$D$2:$D$101,MATCH(27,competitors!$R$2:$R$101,0)),"")} | D28: {=IFERROR(INDEX(competitors!$H$2:$H$101,MATCH(27,competitors!$R$2:$R$101,0)),"")} | E28: {=IFERROR(INDEX(competitors!$I$2:$I$101,MATCH(27,competitors!$R$2:$R$101,0)),"")} | F28: {=IFERROR(INDEX(competitors!$L$2:$L$101,MATCH(27,competitors!$R$2:$R$101,0)),"")} | G28: =IF(B28="","",COUNTIFS(competitors!$C$2:$C$101,B28,competitors!$D$2:$D$101,C28,competitors!$H$2:$H$101,D28,competitors!$I$2:$I$101,E28,competitors!$L$2:$L$101,F28,competitors!$E$2:$E$101,"한국")) | H28: =IF(B28="","",COUNTIFS(competitors!$C$2:$C$101,B28,competitors!$D$2:$D$101,C28,competitors!$H$2:$H$101,D28,competitors!$I$2:$I$101,E28,competitors!$L$2:$L$101,F28)) | I28: =IF(B28="","",IF(G28>=5,"많음",IF(G28>=3,"중간",IF(G28>=1,"적음",IF(H28>=1,"가능","어려움"))))) | J28: {=IF(B28="","",TEXTJOIN(", ",TRUE(),IF((competitors!$C$2:$C$101=B28)*(competitors!$D$2:$D$101=C28)*(competitors!$H$2:$H$101=D28)*(competitors!$I$2:$I$101=E28)*(competitors!$L$2:$L$101=F28),competitors!$B$2:$B$101,"")))} | L28: =IF(B28="","",TODAY())
A29: =IF(B29="","","BM"&TEXT(ROW()-1,"000")) | B29: {=IFERROR(INDEX(competitors!$C$2:$C$101,MATCH(28,competitors!$R$2:$R$101,0)),"")} | C29: {=IFERROR(INDEX(competitors!$D$2:$D$101,MATCH(28,competitors!$R$2:$R$101,0)),"")} | D29: {=IFERROR(INDEX(competitors!$H$2:$H$101,MATCH(28,competitors!$R$2:$R$101,0)),"")} | E29: {=IFERROR(INDEX(competitors!$I$2:$I$101,MATCH(28,competitors!$R$2:$R$101,0)),"")} | F29: {=IFERROR(INDEX(competitors!$L$2:$L$101,MATCH(28,competitors!$R$2:$R$101,0)),"")} | G29: =IF(B29="","",COUNTIFS(competitors!$C$2:$C$101,B29,competitors!$D$2:$D$101,C29,competitors!$H$2:$H$101,D29,competitors!$I$2:$I$101,E29,competitors!$L$2:$L$101,F29,competitors!$E$2:$E$101,"한국")) | H29: =IF(B29="","",COUNTIFS(competitors!$C$2:$C$101,B29,competitors!$D$2:$D$101,C29,competitors!$H$2:$H$101,D29,competitors!$I$2:$I$101,E29,competitors!$L$2:$L$101,F29)) | I29: =IF(B29="","",IF(G29>=5,"많음",IF(G29>=3,"중간",IF(G29>=1,"적음",IF(H29>=1,"가능","어려움"))))) | J29: {=IF(B29="","",TEXTJOIN(", ",TRUE(),IF((competitors!$C$2:$C$101=B29)*(competitors!$D$2:$D$101=C29)*(competitors!$H$2:$H$101=D29)*(competitors!$I$2:$I$101=E29)*(competitors!$L$2:$L$101=F29),competitors!$B$2:$B$101,"")))} | L29: =IF(B29="","",TODAY())
A30: =IF(B30="","","BM"&TEXT(ROW()-1,"000")) | B30: {=IFERROR(INDEX(competitors!$C$2:$C$101,MATCH(29,competitors!$R$2:$R$101,0)),"")} | C30: {=IFERROR(INDEX(competitors!$D$2:$D$101,MATCH(29,competitors!$R$2:$R$101,0)),"")} | D30: {=IFERROR(INDEX(competitors!$H$2:$H$101,MATCH(29,competitors!$R$2:$R$101,0)),"")} | E30: {=IFERROR(INDEX(competitors!$I$2:$I$101,MATCH(29,competitors!$R$2:$R$101,0)),"")} | F30: {=IFERROR(INDEX(competitors!$L$2:$L$101,MATCH(29,competitors!$R$2:$R$101,0)),"")} | G30: =IF(B30="","",COUNTIFS(competitors!$C$2:$C$101,B30,competitors!$D$2:$D$101,C30,competitors!$H$2:$H$101,D30,competitors!$I$2:$I$101,E30,competitors!$L$2:$L$101,F30,competitors!$E$2:$E$101,"한국")) | H30: =IF(B30="","",COUNTIFS(competitors!$C$2:$C$101,B30,competitors!$D$2:$D$101,C30,competitors!$H$2:$H$101,D30,competitors!$I$2:$I$101,E30,competitors!$L$2:$L$101,F30)) | I30: =IF(B30="","",IF(G30>=5,"많음",IF(G30>=3,"중간",IF(G30>=1,"적음",IF(H30>=1,"가능","어려움"))))) | J30: {=IF(B30="","",TEXTJOIN(", ",TRUE(),IF((competitors!$C$2:$C$101=B30)*(competitors!$D$2:$D$101=C30)*(competitors!$H$2:$H$101=D30)*(competitors!$I$2:$I$101=E30)*(competitors!$L$2:$L$101=F30),competitors!$B$2:$B$101,"")))} | L30: =IF(B30="","",TODAY())
A31: =IF(B31="","","BM"&TEXT(ROW()-1,"000")) | B31: {=IFERROR(INDEX(competitors!$C$2:$C$101,MATCH(30,competitors!$R$2:$R$101,0)),"")} | C31: {=IFERROR(INDEX(competitors!$D$2:$D$101,MATCH(30,competitors!$R$2:$R$101,0)),"")} | D31: {=IFERROR(INDEX(competitors!$H$2:$H$101,MATCH(30,competitors!$R$2:$R$101,0)),"")} | E31: {=IFERROR(INDEX(competitors!$I$2:$I$101,MATCH(30,competitors!$R$2:$R$101,0)),"")} | F31: {=IFERROR(INDEX(competitors!$L$2:$L$101,MATCH(30,competitors!$R$2:$R$101,0)),"")} | G31: =IF(B31="","",COUNTIFS(competitors!$C$2:$C$101,B31,competitors!$D$2:$D$101,C31,competitors!$H$2:$H$101,D31,competitors!$I$2:$I$101,E31,competitors!$L$2:$L$101,F31,competitors!$E$2:$E$101,"한국")) | H31: =IF(B31="","",COUNTIFS(competitors!$C$2:$C$101,B31,competitors!$D$2:$D$101,C31,competitors!$H$2:$H$101,D31,competitors!$I$2:$I$101,E31,competitors!$L$2:$L$101,F31)) | I31: =IF(B31="","",IF(G31>=5,"많음",IF(G31>=3,"중간",IF(G31>=1,"적음",IF(H31>=1,"가능","어려움"))))) | J31: {=IF(B31="","",TEXTJOIN(", ",TRUE(),IF((competitors!$C$2:$C$101=B31)*(competitors!$D$2:$D$101=C31)*(competitors!$H$2:$H$101=D31)*(competitors!$I$2:$I$101=E31)*(competitors!$L$2:$L$101=F31),competitors!$B$2:$B$101,"")))} | L31: =IF(B31="","",TODAY())
A32: =IF(B32="","","BM"&TEXT(ROW()-1,"000")) | B32: {=IFERROR(INDEX(competitors!$C$2:$C$101,MATCH(31,competitors!$R$2:$R$101,0)),"")} | C32: {=IFERROR(INDEX(competitors!$D$2:$D$101,MATCH(31,competitors!$R$2:$R$101,0)),"")} | D32: {=IFERROR(INDEX(competitors!$H$2:$H$101,MATCH(31,competitors!$R$2:$R$101,0)),"")} | E32: {=IFERROR(INDEX(competitors!$I$2:$I$101,MATCH(31,competitors!$R$2:$R$101,0)),"")} | F32: {=IFERROR(INDEX(competitors!$L$2:$L$101,MATCH(31,competitors!$R$2:$R$101,0)),"")} | G32: =IF(B32="","",COUNTIFS(competitors!$C$2:$C$101,B32,competitors!$D$2:$D$101,C32,competitors!$H$2:$H$101,D32,competitors!$I$2:$I$101,E32,competitors!$L$2:$L$101,F32,competitors!$E$2:$E$101,"한국")) | H32: =IF(B32="","",COUNTIFS(competitors!$C$2:$C$101,B32,competitors!$D$2:$D$101,C32,competitors!$H$2:$H$101,D32,competitors!$I$2:$I$101,E32,competitors!$L$2:$L$101,F32)) | I32: =IF(B32="","",IF(G32>=5,"많음",IF(G32>=3,"중간",IF(G32>=1,"적음",IF(H32>=1,"가능","어려움"))))) | J32: {=IF(B32="","",TEXTJOIN(", ",TRUE(),IF((competitors!$C$2:$C$101=B32)*(competitors!$D$2:$D$101=C32)*(competitors!$H$2:$H$101=D32)*(competitors!$I$2:$I$101=E32)*(competitors!$L$2:$L$101=F32),competitors!$B$2:$B$101,"")))} | L32: =IF(B32="","",TODAY())
A33: =IF(B33="","","BM"&TEXT(ROW()-1,"000")) | B33: {=IFERROR(INDEX(competitors!$C$2:$C$101,MATCH(32,competitors!$R$2:$R$101,0)),"")} | C33: {=IFERROR(INDEX(competitors!$D$2:$D$101,MATCH(32,competitors!$R$2:$R$101,0)),"")} | D33: {=IFERROR(INDEX(competitors!$H$2:$H$101,MATCH(32,competitors!$R$2:$R$101,0)),"")} | E33: {=IFERROR(INDEX(competitors!$I$2:$I$101,MATCH(32,competitors!$R$2:$R$101,0)),"")} | F33: {=IFERROR(INDEX(competitors!$L$2:$L$101,MATCH(32,competitors!$R$2:$R$101,0)),"")} | G33: =IF(B33="","",COUNTIFS(competitors!$C$2:$C$101,B33,competitors!$D$2:$D$101,C33,competitors!$H$2:$H$101,D33,competitors!$I$2:$I$101,E33,competitors!$L$2:$L$101,F33,competitors!$E$2:$E$101,"한국")) | H33: =IF(B33="","",COUNTIFS(competitors!$C$2:$C$101,B33,competitors!$D$2:$D$101,C33,competitors!$H$2:$H$101,D33,competitors!$I$2:$I$101,E33,competitors!$L$2:$L$101,F33)) | I33: =IF(B33="","",IF(G33>=5,"많음",IF(G33>=3,"중간",IF(G33>=1,"적음",IF(H33>=1,"가능","어려움"))))) | J33: {=IF(B33="","",TEXTJOIN(", ",TRUE(),IF((competitors!$C$2:$C$101=B33)*(competitors!$D$2:$D$101=C33)*(competitors!$H$2:$H$101=D33)*(competitors!$I$2:$I$101=E33)*(competitors!$L$2:$L$101=F33),competitors!$B$2:$B$101,"")))} | L33: =IF(B33="","",TODAY())
